Workbook

Sheet Budget
A1: Family Budget Planner - | D1: ='Section-Category'!D1 -> 2026
A2: Starting Balance:
A3: 1776341.3
B4: AG | C4: AF | D4: AG | E4: AF | F4: AH | G4: AF | H4: AF | I4: AF | J4: AF | K4: AG | L4: AF | M4: AG
A5: Goal: Saving For My Daughter
A6: Summary | B6: Jan | C6: Feb | D6: Mar | E6: Apr | F6: May | G6: Jun | H6: Jul | I6: Aug | J6: Sep | K6: Oct | L6: Nov | M6: Dec | N6: Total | O6: Avg
A7: BUDGET REMINDER
A8: Balance I Can Used (Bank) | O8: =SUM(C8:N8) -> 0
A9: Balance I have Left (Bank) | B9: =IF(OR(B$8="#",TRIM(B$18)="0"),"0",B8-B17) -> 0 | C9: =IF(OR(C$8="#",TRIM(C$18)="0"),"0",C8-C17) -> 0 | D9: =IF(OR(D$8="#",TRIM(D$18)="0"),"0",D8-D17) -> 0 | E9: =IF(OR(E$8="#",TRIM(E$18)="0"),"0",E8-E17) -> 0 | F9: =F8-F17 -> 0 | G9: =IF(OR(G$8="#",TRIM(G$18)="0"),"0",G8-G17) -> 0 | H9: =IF(OR(H$8="#",TRIM(H$18)="0"),"0",H8-H17) -> 0 | I9: =IF(OR(I$8="#",TRIM(I$18)="0"),"0",I8-I17) -> 0 | J9: =IF(OR(J$8="#",TRIM(J$18)="0"),"0",J8-J17) -> 0 | K9: =IF(OR(K$8="#",TRIM(K$18)="0"),"0",K8-K17) -> 0 | L9: =IF(OR(L$8="#",TRIM(L$18)="0"),"0",L8-L17) -> 0 | M9: =IF(OR(M$8="#",TRIM(M$18)="0"),"0",M8-M17) -> 0 | N9: =IF(OR(N$8="#",TRIM(N$18)="0"),"-",N8-N17) -> - | O9: =SUM(C9:N9) -> 0
A10: PETTY CASH
A11: Petty Cash | N11: =SUM(B11:M11) -> 0 | O11: =SUM(C11:N11) -> 0
A12: Petty Cash Used | B12: =IF(TRIM(B$54)="0","0",B54) -> 0 | C12: =IF(TRIM(C$54)="0","0",C54) -> 0 | D12: =IF(TRIM(D$54)="0","0",D54) -> 0 | E12: =IF(TRIM(E$54)="0","0",E54) -> 0 | F12: =IF(TRIM(F$54)="0","0",F54) -> 0 | G12: =IF(TRIM(G$54)="0","0",G54) -> 0 | H12: =IF(TRIM(H$54)="0","0",H54) -> 0 | I12: =IF(TRIM(I$54)="0","0",I54) -> 0 | ... M12: =IF(TRIM(M$54)="0","0",M54) -> 0 | N12: =SUM(B12:M12) -> 0 | O12: =SUM(C12:N12) -> 0
A14: Current Balance (Petty Cash) | B14: =IF(TRIM(B$11)="0","",B11-B12) -> 0 | C14: =IF(TRIM(C$11)="0","",C11-C12) -> 0 | D14: =IF(TRIM(D$11)="0","",D11-D12) -> 0 | E14: =IF(TRIM(E$11)="0","",E11-E12) -> 0 | F14: =IF(TRIM(F$11)="0","",F11-F12) -> 0 | G14: =IF(TRIM(G$11)="0","",G11-G12) -> 0 | H14: =IF(TRIM(H$11)="0","",H11-H12) -> 0 | I14: =IF(TRIM(I$11)="0","",I11-I12) -> 0 | ... N14: =IF(TRIM(N$11)="0","",N11-N12) | O14: =O11-O12 -> 0
A15: BANK
A16: Total Income | B16: =B43 -> 0 | C16: =C43 -> 0 | D16: =D43 -> 0 | E16: =E43 -> 0 | F16: =F43 -> 0 | G16: =G43 -> 0 | H16: =H43 -> 0 | I16: =I43 -> 0 | ... M16: =M43 -> 0 | N16: =SUM(B16:M16) -> 0 | O16: =N16/COLUMNS(B16:M16) -> 0
A17: Total Expenses | B17: =B63+B80+B94+B106+B116+B125+B134+B142+B150+B158+B173+B181+B191+B201+B210 -> 0 | C17: =C63+C80+C94+C106+C116+C125+C134+C142+C150+C158+C173+C181+C191+C201+C210 -> 0 | D17: =D63+D80+D94+D106+D116+D125+D134+D142+D150+D158+D173+D181+D191+D201+D210 -> 0 | E17: =E63+E80+E94+E106+E116+E125+E134+E142+E150+E158+E173+E181+E191+E201+E210 -> 0 | F17: =F63+F80+F94+F106+F116+F125+F134+F142+F150+F158+F173+F181+F191+F201+F210 -> 0 | G17: =G63+G80+G94+G106+G116+G125+G134+G142+G150+G158+G173+G181+G191+G201+G210 -> 0 | H17: =H63+H80+H94+H106+H116+H125+H134+H142+H150+H158+H173+H181+H191+H201+H210 -> 0 | I17: =I63+I80+I94+I106+I116+I125+I134+I142+I150+I158+I173+I181+I191+I201+I210 -> 0 | ... M17: =M63+M80+M94+M106+M116+M125+M134+M142+M150+M158+M173+M181+M191+M201+M210 -> 0 | N17: =SUM(B17:M17) -> 0 | O17: =N17/COLUMNS(B17:M17) -> 0
A18: NET (Income - Expenses) | B18: =B16-B17 -> 0 | C18: =C16-C17 -> 0 | D18: =D16-D17 -> 0 | E18: =E16-E17 -> 0 | F18: =F16-F17 -> 0 | G18: =G16-G17 -> 0 | H18: =H16-H17 -> 0 | I18: =I16-I17 -> 0 | ... M18: =M16-M17 -> 0 | N18: =SUM(B18:M18) -> 0 | O18: =N18/COLUMNS(B18:M18) -> 0
A20: Current Balance (In Bank) | B20: =A3+B18 -> 1776341.3 | C20: =B21+C18 -> 1776341.3 | D20: =C21+D18 -> 1776341.3 | E20: =D21+E18 -> 1776341.3 | F20: =IF(F$11=0,"-",E20+F18) -> - | G20: =IF(G$11=0,"-",F20+G18) -> - | H20: =IF(H$11=0,"-",G20+H18) -> - | I20: =IF(I$11=0,"-",H20+I18) -> - | J20: =IF(J$11=0,"-",I20+J18) -> - | K20: =IF(K$11=0,"-",J20+K18) -> - | L20: =IF(L$11=0,"-",K20+L18) -> - | M20: =IF(M$11=0,"-",L20+M18) -> -
A21: Saving Total (Cash + Bank) | B21: =B20+B14 -> 1776341.3 | C21: =C20+C14 -> 1776341.3 | D21: =D20+D14 -> 1776341.3 | E21: =E20+E14 -> 1776341.3 | F21: =F20+F14 -> #VALUE! | G21: =IF(G$11=0,"-",G14+G20) -> - | H21: =IF(H$11=0,"-",H14+H20) -> - | I21: =IF(I$11=0,"-",I14+I20) -> - | J21: =IF(J$11=0,"-",J14+J20) -> - | K21: =IF(K$11=0,"-",K14+K20) -> - | L21: =IF(L$11=0,"-",L14+L20) -> - | M21: =IF(M$11=0,"-",M14+M20) -> -
A35: ='Section-Category'!A1 -> INCOME | B35: =B$6 -> Jan | C35: =C$6 -> Feb | D35: =D$6 -> Mar | E35: =E$6 -> Apr | F35: =F$6 -> May | G35: =G$6 -> Jun | H35: =H$6 -> Jul | I35: =I$6 -> Aug | ... M35: =M$6 -> Dec | N35: Total | O35: Avg
A36: ='Section-Category'!A2 -> Wages & Tips | B36: {=IF(OR(TRIM(INDIRECT("'"&B$6&"'!"&B$4&ROW()-31))="0",INDIRECT("'"&B$6&"'!"&B$4&ROW()-31)="",NOT(ISNUMBER(INDIRECT("'"&B$6&"'!"&B$4&ROW()-31)))),"-",INDIRECT("'"&B$6&"'!"&B$4&ROW()-31))} -> - | C36: {=IF(OR(TRIM(INDIRECT("'"&C$6&"'!"&C$4&ROW()-31))="0",INDIRECT("'"&C$6&"'!"&C$4&ROW()-31)="",NOT(ISNUMBER(INDIRECT("'"&C$6&"'!"&C$4&ROW()-31)))),"-",INDIRECT("'"&C$6&"'!"&C$4&ROW()-31))} -> - | D36: {=IF(OR(TRIM(INDIRECT("'"&D$6&"'!"&D$4&ROW()-31))="0",INDIRECT("'"&D$6&"'!"&D$4&ROW()-31)="",NOT(ISNUMBER(INDIRECT("'"&D$6&"'!"&D$4&ROW()-31)))),"-",INDIRECT("'"&D$6&"'!"&D$4&ROW()-31))} -> - | E36: {=IF(OR(TRIM(INDIRECT("'"&E$6&"'!"&E$4&ROW()-31))="0",INDIRECT("'"&E$6&"'!"&E$4&ROW()-31)="",NOT(ISNUMBER(INDIRECT("'"&E$6&"'!"&E$4&ROW()-31)))),"-",INDIRECT("'"&E$6&"'!"&E$4&ROW()-31))} -> - | F36: {=IF(OR(TRIM(INDIRECT("'"&F$6&"'!"&F$4&ROW()-31))="0",INDIRECT("'"&F$6&"'!"&F$4&ROW()-31)="",NOT(ISNUMBER(INDIRECT("'"&F$6&"'!"&F$4&ROW()-31)))),"-",INDIRECT("'"&F$6&"'!"&F$4&ROW()-31))} -> - | G36: {=IF(OR(TRIM(INDIRECT("'"&G$6&"'!"&G$4&ROW()-31))="0",INDIRECT("'"&G$6&"'!"&G$4&ROW()-31)="",NOT(ISNUMBER(INDIRECT("'"&G$6&"'!"&G$4&ROW()-31)))),"-",INDIRECT("'"&G$6&"'!"&G$4&ROW()-31))} -> - | H36: {=IF(OR(TRIM(INDIRECT("'"&H$6&"'!"&H$4&ROW()-31))="0",INDIRECT("'"&H$6&"'!"&H$4&ROW()-31)="",NOT(ISNUMBER(INDIRECT("'"&H$6&"'!"&H$4&ROW()-31)))),"-",INDIRECT("'"&H$6&"'!"&H$4&ROW()-31))} -> - | I36: {=IF(OR(TRIM(INDIRECT("'"&I$6&"'!"&I$4&ROW()-31))="0",INDIRECT("'"&I$6&"'!"&I$4&ROW()-31)="",NOT(ISNUMBER(INDIRECT("'"&I$6&"'!"&I$4&ROW()-31)))),"-",INDIRECT("'"&I$6&"'!"&I$4&ROW()-31))} -> - | ... M36: {=IF(OR(TRIM(INDIRECT("'"&M$6&"'!"&M$4&ROW()-31))="0",INDIRECT("'"&M$6&"'!"&M$4&ROW()-31)="",NOT(ISNUMBER(INDIRECT("'"&M$6&"'!"&M$4&ROW()-31)))),"-",INDIRECT("'"&M$6&"'!"&M$4&ROW()-31))} -> - | N36: =SUM(B36:M36) -> 0 | O36: =N36/COLUMNS(B36:M36) -> 0
A37: ='Section-Category'!A3 -> Interest Income | B37: {=IF(OR(TRIM(INDIRECT("'"&B$6&"'!"&B$4&ROW()-31))="0",INDIRECT("'"&B$6&"'!"&B$4&ROW()-31)="",NOT(ISNUMBER(INDIRECT("'"&B$6&"'!"&B$4&ROW()-31)))),"-",INDIRECT("'"&B$6&"'!"&B$4&ROW()-31))} -> - | C37: {=IF(OR(TRIM(INDIRECT("'"&C$6&"'!"&C$4&ROW()-31))="0",INDIRECT("'"&C$6&"'!"&C$4&ROW()-31)="",NOT(ISNUMBER(INDIRECT("'"&C$6&"'!"&C$4&ROW()-31)))),"-",INDIRECT("'"&C$6&"'!"&C$4&ROW()-31))} -> - | D37: {=IF(OR(TRIM(INDIRECT("'"&D$6&"'!"&D$4&ROW()-31))="0",INDIRECT("'"&D$6&"'!"&D$4&ROW()-31)="",NOT(ISNUMBER(INDIRECT("'"&D$6&"'!"&D$4&ROW()-31)))),"-",INDIRECT("'"&D$6&"'!"&D$4&ROW()-31))} -> - | E37: {=IF(OR(TRIM(INDIRECT("'"&E$6&"'!"&E$4&ROW()-31))="0",INDIRECT("'"&E$6&"'!"&E$4&ROW()-31)="",NOT(ISNUMBER(INDIRECT("'"&E$6&"'!"&E$4&ROW()-31)))),"-",INDIRECT("'"&E$6&"'!"&E$4&ROW()-31))} -> - | F37: {=IF(OR(TRIM(INDIRECT("'"&F$6&"'!"&F$4&ROW()-31))="0",INDIRECT("'"&F$6&"'!"&F$4&ROW()-31)="",NOT(ISNUMBER(INDIRECT("'"&F$6&"'!"&F$4&ROW()-31)))),"-",INDIRECT("'"&F$6&"'!"&F$4&ROW()-31))} -> - | G37: {=IF(OR(TRIM(INDIRECT("'"&G$6&"'!"&G$4&ROW()-31))="0",INDIRECT("'"&G$6&"'!"&G$4&ROW()-31)="",NOT(ISNUMBER(INDIRECT("'"&G$6&"'!"&G$4&ROW()-31)))),"-",INDIRECT("'"&G$6&"'!"&G$4&ROW()-31))} -> - | H37: {=IF(OR(TRIM(INDIRECT("'"&H$6&"'!"&H$4&ROW()-31))="0",INDIRECT("'"&H$6&"'!"&H$4&ROW()-31)="",NOT(ISNUMBER(INDIRECT("'"&H$6&"'!"&H$4&ROW()-31)))),"-",INDIRECT("'"&H$6&"'!"&H$4&ROW()-31))} -> - | I37: {=IF(OR(TRIM(INDIRECT("'"&I$6&"'!"&I$4&ROW()-31))="0",INDIRECT("'"&I$6&"'!"&I$4&ROW()-31)="",NOT(ISNUMBER(INDIRECT("'"&I$6&"'!"&I$4&ROW()-31)))),"-",INDIRECT("'"&I$6&"'!"&I$4&ROW()-31))} -> - | ... M37: {=IF(OR(TRIM(INDIRECT("'"&M$6&"'!"&M$4&ROW()-31))="0",INDIRECT("'"&M$6&"'!"&M$4&ROW()-31)="",NOT(ISNUMBER(INDIRECT("'"&M$6&"'!"&M$4&ROW()-31)))),"-",INDIRECT("'"&M$6&"'!"&M$4&ROW()-31))} -> - | N37: =SUM(B37:M37) -> 0 | O37: =N37/COLUMNS(B37:M37) -> 0
A38: ='Section-Category'!A4 -> Dividends | B38: {=IF(OR(TRIM(INDIRECT("'"&B$6&"'!"&B$4&ROW()-31))="0",INDIRECT("'"&B$6&"'!"&B$4&ROW()-31)="",NOT(ISNUMBER(INDIRECT("'"&B$6&"'!"&B$4&ROW()-31)))),"-",INDIRECT("'"&B$6&"'!"&B$4&ROW()-31))} -> - | C38: {=IF(OR(TRIM(INDIRECT("'"&C$6&"'!"&C$4&ROW()-31))="0",INDIRECT("'"&C$6&"'!"&C$4&ROW()-31)="",NOT(ISNUMBER(INDIRECT("'"&C$6&"'!"&C$4&ROW()-31)))),"-",INDIRECT("'"&C$6&"'!"&C$4&ROW()-31))} -> - | D38: {=IF(OR(TRIM(INDIRECT("'"&D$6&"'!"&D$4&ROW()-31))="0",INDIRECT("'"&D$6&"'!"&D$4&ROW()-31)="",NOT(ISNUMBER(INDIRECT("'"&D$6&"'!"&D$4&ROW()-31)))),"-",INDIRECT("'"&D$6&"'!"&D$4&ROW()-31))} -> - | E38: {=IF(OR(TRIM(INDIRECT("'"&E$6&"'!"&E$4&ROW()-31))="0",INDIRECT("'"&E$6&"'!"&E$4&ROW()-31)="",NOT(ISNUMBER(INDIRECT("'"&E$6&"'!"&E$4&ROW()-31)))),"-",INDIRECT("'"&E$6&"'!"&E$4&ROW()-31))} -> - | F38: {=IF(OR(TRIM(INDIRECT("'"&F$6&"'!"&F$4&ROW()-31))="0",INDIRECT("'"&F$6&"'!"&F$4&ROW()-31)="",NOT(ISNUMBER(INDIRECT("'"&F$6&"'!"&F$4&ROW()-31)))),"-",INDIRECT("'"&F$6&"'!"&F$4&ROW()-31))} -> - | G38: {=IF(OR(TRIM(INDIRECT("'"&G$6&"'!"&G$4&ROW()-31))="0",INDIRECT("'"&G$6&"'!"&G$4&ROW()-31)="",NOT(ISNUMBER(INDIRECT("'"&G$6&"'!"&G$4&ROW()-31)))),"-",INDIRECT("'"&G$6&"'!"&G$4&ROW()-31))} -> - | H38: {=IF(OR(TRIM(INDIRECT("'"&H$6&"'!"&H$4&ROW()-31))="0",INDIRECT("'"&H$6&"'!"&H$4&ROW()-31)="",NOT(ISNUMBER(INDIRECT("'"&H$6&"'!"&H$4&ROW()-31)))),"-",INDIRECT("'"&H$6&"'!"&H$4&ROW()-31))} -> - | I38: {=IF(OR(TRIM(INDIRECT("'"&I$6&"'!"&I$4&ROW()-31))="0",INDIRECT("'"&I$6&"'!"&I$4&ROW()-31)="",NOT(ISNUMBER(INDIRECT("'"&I$6&"'!"&I$4&ROW()-31)))),"-",INDIRECT("'"&I$6&"'!"&I$4&ROW()-31))} -> - | ... M38: {=IF(OR(TRIM(INDIRECT("'"&M$6&"'!"&M$4&ROW()-31))="0",INDIRECT("'"&M$6&"'!"&M$4&ROW()-31)="",NOT(ISNUMBER(INDIRECT("'"&M$6&"'!"&M$4&ROW()-31)))),"-",INDIRECT("'"&M$6&"'!"&M$4&ROW()-31))} -> - | N38: =SUM(B38:M38) -> 0 | O38: =N38/COLUMNS(B38:M38) -> 0
A39: ='Section-Category'!A5 -> Gifts Received | B39: {=IF(OR(TRIM(INDIRECT("'"&B$6&"'!"&B$4&ROW()-31))="0",INDIRECT("'"&B$6&"'!"&B$4&ROW()-31)="",NOT(ISNUMBER(INDIRECT("'"&B$6&"'!"&B$4&ROW()-31)))),"-",INDIRECT("'"&B$6&"'!"&B$4&ROW()-31))} -> - | C39: {=IF(OR(TRIM(INDIRECT("'"&C$6&"'!"&C$4&ROW()-31))="0",INDIRECT("'"&C$6&"'!"&C$4&ROW()-31)="",NOT(ISNUMBER(INDIRECT("'"&C$6&"'!"&C$4&ROW()-31)))),"-",INDIRECT("'"&C$6&"'!"&C$4&ROW()-31))} -> - | D39: {=IF(OR(TRIM(INDIRECT("'"&D$6&"'!"&D$4&ROW()-31))="0",INDIRECT("'"&D$6&"'!"&D$4&ROW()-31)="",NOT(ISNUMBER(INDIRECT("'"&D$6&"'!"&D$4&ROW()-31)))),"-",INDIRECT("'"&D$6&"'!"&D$4&ROW()-31))} -> - | E39: {=IF(OR(TRIM(INDIRECT("'"&E$6&"'!"&E$4&ROW()-31))="0",INDIRECT("'"&E$6&"'!"&E$4&ROW()-31)="",NOT(ISNUMBER(INDIRECT("'"&E$6&"'!"&E$4&ROW()-31)))),"-",INDIRECT("'"&E$6&"'!"&E$4&ROW()-31))} -> - | F39: {=IF(OR(TRIM(INDIRECT("'"&F$6&"'!"&F$4&ROW()-31))="0",INDIRECT("'"&F$6&"'!"&F$4&ROW()-31)="",NOT(ISNUMBER(INDIRECT("'"&F$6&"'!"&F$4&ROW()-31)))),"-",INDIRECT("'"&F$6&"'!"&F$4&ROW()-31))} -> - | G39: {=IF(OR(TRIM(INDIRECT("'"&G$6&"'!"&G$4&ROW()-31))="0",INDIRECT("'"&G$6&"'!"&G$4&ROW()-31)="",NOT(ISNUMBER(INDIRECT("'"&G$6&"'!"&G$4&ROW()-31)))),"-",INDIRECT("'"&G$6&"'!"&G$4&ROW()-31))} -> - | H39: {=IF(OR(TRIM(INDIRECT("'"&H$6&"'!"&H$4&ROW()-31))="0",INDIRECT("'"&H$6&"'!"&H$4&ROW()-31)="",NOT(ISNUMBER(INDIRECT("'"&H$6&"'!"&H$4&ROW()-31)))),"-",INDIRECT("'"&H$6&"'!"&H$4&ROW()-31))} -> - | I39: {=IF(OR(TRIM(INDIRECT("'"&I$6&"'!"&I$4&ROW()-31))="0",INDIRECT("'"&I$6&"'!"&I$4&ROW()-31)="",NOT(ISNUMBER(INDIRECT("'"&I$6&"'!"&I$4&ROW()-31)))),"-",INDIRECT("'"&I$6&"'!"&I$4&ROW()-31))} -> - | ... M39: {=IF(OR(TRIM(INDIRECT("'"&M$6&"'!"&M$4&ROW()-31))="0",INDIRECT("'"&M$6&"'!"&M$4&ROW()-31)="",NOT(ISNUMBER(INDIRECT("'"&M$6&"'!"&M$4&ROW()-31)))),"-",INDIRECT("'"&M$6&"'!"&M$4&ROW()-31))} -> - | N39: =SUM(B39:M39) -> 0 | O39: =N39/COLUMNS(B39:M39) -> 0
A40: ='Section-Category'!A6 -> Refunds/Reimbursements | B40: {=IF(OR(TRIM(INDIRECT("'"&B$6&"'!"&B$4&ROW()-31))="0",INDIRECT("'"&B$6&"'!"&B$4&ROW()-31)="",NOT(ISNUMBER(INDIRECT("'"&B$6&"'!"&B$4&ROW()-31)))),"-",INDIRECT("'"&B$6&"'!"&B$4&ROW()-31))} -> - | C40: {=IF(OR(TRIM(INDIRECT("'"&C$6&"'!"&C$4&ROW()-31))="0",INDIRECT("'"&C$6&"'!"&C$4&ROW()-31)="",NOT(ISNUMBER(INDIRECT("'"&C$6&"'!"&C$4&ROW()-31)))),"-",INDIRECT("'"&C$6&"'!"&C$4&ROW()-31))} -> - | D40: {=IF(OR(TRIM(INDIRECT("'"&D$6&"'!"&D$4&ROW()-31))="0",INDIRECT("'"&D$6&"'!"&D$4&ROW()-31)="",NOT(ISNUMBER(INDIRECT("'"&D$6&"'!"&D$4&ROW()-31)))),"-",INDIRECT("'"&D$6&"'!"&D$4&ROW()-31))} -> - | E40: {=IF(OR(TRIM(INDIRECT("'"&E$6&"'!"&E$4&ROW()-31))="0",INDIRECT("'"&E$6&"'!"&E$4&ROW()-31)="",NOT(ISNUMBER(INDIRECT("'"&E$6&"'!"&E$4&ROW()-31)))),"-",INDIRECT("'"&E$6&"'!"&E$4&ROW()-31))} -> - | F40: {=IF(OR(TRIM(INDIRECT("'"&F$6&"'!"&F$4&ROW()-31))="0",INDIRECT("'"&F$6&"'!"&F$4&ROW()-31)="",NOT(ISNUMBER(INDIRECT("'"&F$6&"'!"&F$4&ROW()-31)))),"-",INDIRECT("'"&F$6&"'!"&F$4&ROW()-31))} -> - | G40: {=IF(OR(TRIM(INDIRECT("'"&G$6&"'!"&G$4&ROW()-31))="0",INDIRECT("'"&G$6&"'!"&G$4&ROW()-31)="",NOT(ISNUMBER(INDIRECT("'"&G$6&"'!"&G$4&ROW()-31)))),"-",INDIRECT("'"&G$6&"'!"&G$4&ROW()-31))} -> - | H40: {=IF(OR(TRIM(INDIRECT("'"&H$6&"'!"&H$4&ROW()-31))="0",INDIRECT("'"&H$6&"'!"&H$4&ROW()-31)="",NOT(ISNUMBER(INDIRECT("'"&H$6&"'!"&H$4&ROW()-31)))),"-",INDIRECT("'"&H$6&"'!"&H$4&ROW()-31))} -> - | I40: {=IF(OR(TRIM(INDIRECT("'"&I$6&"'!"&I$4&ROW()-31))="0",INDIRECT("'"&I$6&"'!"&I$4&ROW()-31)="",NOT(ISNUMBER(INDIRECT("'"&I$6&"'!"&I$4&ROW()-31)))),"-",INDIRECT("'"&I$6&"'!"&I$4&ROW()-31))} -> - | ... M40: {=IF(OR(TRIM(INDIRECT("'"&M$6&"'!"&M$4&ROW()-31))="0",INDIRECT("'"&M$6&"'!"&M$4&ROW()-31)="",NOT(ISNUMBER(INDIRECT("'"&M$6&"'!"&M$4&ROW()-31)))),"-",INDIRECT("'"&M$6&"'!"&M$4&ROW()-31))} -> - | N40: =SUM(B40:M40) -> 0 | O40: =N40/COLUMNS(B40:M40) -> 0
A41: ='Section-Category'!A7 -> Other | B41: {=IF(OR(TRIM(INDIRECT("'"&B$6&"'!"&B$4&ROW()-31))="0",INDIRECT("'"&B$6&"'!"&B$4&ROW()-31)="",NOT(ISNUMBER(INDIRECT("'"&B$6&"'!"&B$4&ROW()-31)))),"-",INDIRECT("'"&B$6&"'!"&B$4&ROW()-31))} -> - | C41: {=IF(OR(TRIM(INDIRECT("'"&C$6&"'!"&C$4&ROW()-31))="0",INDIRECT("'"&C$6&"'!"&C$4&ROW()-31)="",NOT(ISNUMBER(INDIRECT("'"&C$6&"'!"&C$4&ROW()-31)))),"-",INDIRECT("'"&C$6&"'!"&C$4&ROW()-31))} -> - | D41: {=IF(OR(TRIM(INDIRECT("'"&D$6&"'!"&D$4&ROW()-31))="0",INDIRECT("'"&D$6&"'!"&D$4&ROW()-31)="",NOT(ISNUMBER(INDIRECT("'"&D$6&"'!"&D$4&ROW()-31)))),"-",INDIRECT("'"&D$6&"'!"&D$4&ROW()-31))} -> - | E41: {=IF(OR(TRIM(INDIRECT("'"&E$6&"'!"&E$4&ROW()-31))="0",INDIRECT("'"&E$6&"'!"&E$4&ROW()-31)="",NOT(ISNUMBER(INDIRECT("'"&E$6&"'!"&E$4&ROW()-31)))),"-",INDIRECT("'"&E$6&"'!"&E$4&ROW()-31))} -> - | F41: {=IF(OR(TRIM(INDIRECT("'"&F$6&"'!"&F$4&ROW()-31))="0",INDIRECT("'"&F$6&"'!"&F$4&ROW()-31)="",NOT(ISNUMBER(INDIRECT("'"&F$6&"'!"&F$4&ROW()-31)))),"-",INDIRECT("'"&F$6&"'!"&F$4&ROW()-31))} -> - | G41: {=IF(OR(TRIM(INDIRECT("'"&G$6&"'!"&G$4&ROW()-31))="0",INDIRECT("'"&G$6&"'!"&G$4&ROW()-31)="",NOT(ISNUMBER(INDIRECT("'"&G$6&"'!"&G$4&ROW()-31)))),"-",INDIRECT("'"&G$6&"'!"&G$4&ROW()-31))} -> - | H41: {=IF(OR(TRIM(INDIRECT("'"&H$6&"'!"&H$4&ROW()-31))="0",INDIRECT("'"&H$6&"'!"&H$4&ROW()-31)="",NOT(ISNUMBER(INDIRECT("'"&H$6&"'!"&H$4&ROW()-31)))),"-",INDIRECT("'"&H$6&"'!"&H$4&ROW()-31))} -> - | I41: {=IF(OR(TRIM(INDIRECT("'"&I$6&"'!"&I$4&ROW()-31))="0",INDIRECT("'"&I$6&"'!"&I$4&ROW()-31)="",NOT(ISNUMBER(INDIRECT("'"&I$6&"'!"&I$4&ROW()-31)))),"-",INDIRECT("'"&I$6&"'!"&I$4&ROW()-31))} -> - | ... M41: {=IF(OR(TRIM(INDIRECT("'"&M$6&"'!"&M$4&ROW()-31))="0",INDIRECT("'"&M$6&"'!"&M$4&ROW()-31)="",NOT(ISNUMBER(INDIRECT("'"&M$6&"'!"&M$4&ROW()-31)))),"-",INDIRECT("'"&M$6&"'!"&M$4&ROW()-31))} -> - | N41: =SUM(B41:M41) -> 0 | O41: =N41/COLUMNS(B41:M41) -> 0
A42: ='Section-Category'!A8 -> Transfer From Savings | B42: {=IF(OR(TRIM(INDIRECT("'"&B$6&"'!"&B$4&ROW()-31))="0",INDIRECT("'"&B$6&"'!"&B$4&ROW()-31)="",NOT(ISNUMBER(INDIRECT("'"&B$6&"'!"&B$4&ROW()-31)))),"-",INDIRECT("'"&B$6&"'!"&B$4&ROW()-31))} -> - | C42: {=IF(OR(TRIM(INDIRECT("'"&C$6&"'!"&C$4&ROW()-31))="0",INDIRECT("'"&C$6&"'!"&C$4&ROW()-31)="",NOT(ISNUMBER(INDIRECT("'"&C$6&"'!"&C$4&ROW()-31)))),"-",INDIRECT("'"&C$6&"'!"&C$4&ROW()-31))} -> - | D42: {=IF(OR(TRIM(INDIRECT("'"&D$6&"'!"&D$4&ROW()-31))="0",INDIRECT("'"&D$6&"'!"&D$4&ROW()-31)="",NOT(ISNUMBER(INDIRECT("'"&D$6&"'!"&D$4&ROW()-31)))),"-",INDIRECT("'"&D$6&"'!"&D$4&ROW()-31))} -> - | E42: {=IF(OR(TRIM(INDIRECT("'"&E$6&"'!"&E$4&ROW()-31))="0",INDIRECT("'"&E$6&"'!"&E$4&ROW()-31)="",NOT(ISNUMBER(INDIRECT("'"&E$6&"'!"&E$4&ROW()-31)))),"-",INDIRECT("'"&E$6&"'!"&E$4&ROW()-31))} -> - | F42: {=IF(OR(TRIM(INDIRECT("'"&F$6&"'!"&F$4&ROW()-31))="0",INDIRECT("'"&F$6&"'!"&F$4&ROW()-31)="",NOT(ISNUMBER(INDIRECT("'"&F$6&"'!"&F$4&ROW()-31)))),"-",INDIRECT("'"&F$6&"'!"&F$4&ROW()-31))} -> - | G42: {=IF(OR(TRIM(INDIRECT("'"&G$6&"'!"&G$4&ROW()-31))="0",INDIRECT("'"&G$6&"'!"&G$4&ROW()-31)="",NOT(ISNUMBER(INDIRECT("'"&G$6&"'!"&G$4&ROW()-31)))),"-",INDIRECT("'"&G$6&"'!"&G$4&ROW()-31))} -> - | H42: {=IF(OR(TRIM(INDIRECT("'"&H$6&"'!"&H$4&ROW()-31))="0",INDIRECT("'"&H$6&"'!"&H$4&ROW()-31)="",NOT(ISNUMBER(INDIRECT("'"&H$6&"'!"&H$4&ROW()-31)))),"-",INDIRECT("'"&H$6&"'!"&H$4&ROW()-31))} -> - | I42: {=IF(OR(TRIM(INDIRECT("'"&I$6&"'!"&I$4&ROW()-31))="0",INDIRECT("'"&I$6&"'!"&I$4&ROW()-31)="",NOT(ISNUMBER(INDIRECT("'"&I$6&"'!"&I$4&ROW()-31)))),"-",INDIRECT("'"&I$6&"'!"&I$4&ROW()-31))} -> - | ... M42: {=IF(OR(TRIM(INDIRECT("'"&M$6&"'!"&M$4&ROW()-31))="0",INDIRECT("'"&M$6&"'!"&M$4&ROW()-31)="",NOT(ISNUMBER(INDIRECT("'"&M$6&"'!"&M$4&ROW()-31)))),"-",INDIRECT("'"&M$6&"'!"&M$4&ROW()-31))} -> - | N42: =SUM(B42:M42) -> 0 | O42: =N42/COLUMNS(B42:M42) -> 0
A43: Total INCOME | B43: =SUM(B36:B42) -> 0 | C43: =SUM(C36:C42) -> 0 | D43: =SUM(D36:D42) -> 0 | E43: =SUM(E36:E42) -> 0 | F43: =SUM(F36:F42) -> 0 | G43: =SUM(G36:G42) -> 0 | H43: =SUM(H36:H42) -> 0 | I43: =SUM(I36:I42) -> 0 | ... O43: =SUM(O36:O42) -> 0
A45: ='Section-Category'!A82 -> Petty Cash Used | B45: =B$6 -> Jan | C45: =C$6 -> Feb | D45: =D$6 -> Mar | E45: =E$6 -> Apr | F45: =F$6 -> May | G45: =G$6 -> Jun | H45: =H$6 -> Jul | I45: =I$6 -> Aug | ... M45: =M$6 -> Dec
A46: ='Section-Category'!A83 -> Pocket Money Wife | B46: {=IF(OR(TRIM(INDIRECT("'"&B$6&"'!"&B$4&ROW()-31))="0",INDIRECT("'"&B$6&"'!"&B$4&ROW()-31)="",NOT(ISNUMBER(INDIRECT("'"&B$6&"'!"&B$4&ROW()-31)))),"-",INDIRECT("'"&B$6&"'!"&B$4&ROW()-31))} -> - | C46: {=IF(OR(TRIM(INDIRECT("'"&C$6&"'!"&C$4&ROW()-31))="0",INDIRECT("'"&C$6&"'!"&C$4&ROW()-31)="",NOT(ISNUMBER(INDIRECT("'"&C$6&"'!"&C$4&ROW()-31)))),"-",INDIRECT("'"&C$6&"'!"&C$4&ROW()-31))} -> - | D46: {=IF(OR(TRIM(INDIRECT("'"&D$6&"'!"&D$4&ROW()-31))="0",INDIRECT("'"&D$6&"'!"&D$4&ROW()-31)="",NOT(ISNUMBER(INDIRECT("'"&D$6&"'!"&D$4&ROW()-31)))),"-",INDIRECT("'"&D$6&"'!"&D$4&ROW()-31))} -> - | E46: {=IF(OR(TRIM(INDIRECT("'"&E$6&"'!"&E$4&ROW()-31))="0",INDIRECT("'"&E$6&"'!"&E$4&ROW()-31)="",NOT(ISNUMBER(INDIRECT("'"&E$6&"'!"&E$4&ROW()-31)))),"-",INDIRECT("'"&E$6&"'!"&E$4&ROW()-31))} -> - | F46: {=IF(OR(TRIM(INDIRECT("'"&F$6&"'!"&F$4&ROW()-31))="0",INDIRECT("'"&F$6&"'!"&F$4&ROW()-31)="",NOT(ISNUMBER(INDIRECT("'"&F$6&"'!"&F$4&ROW()-31)))),"-",INDIRECT("'"&F$6&"'!"&F$4&ROW()-31))} -> - | G46: {=IF(OR(TRIM(INDIRECT("'"&G$6&"'!"&G$4&ROW()-31))="0",INDIRECT("'"&G$6&"'!"&G$4&ROW()-31)="",NOT(ISNUMBER(INDIRECT("'"&G$6&"'!"&G$4&ROW()-31)))),"-",INDIRECT("'"&G$6&"'!"&G$4&ROW()-31))} -> - | H46: {=IF(OR(TRIM(INDIRECT("'"&H$6&"'!"&H$4&ROW()-31))="0",INDIRECT("'"&H$6&"'!"&H$4&ROW()-31)="",NOT(ISNUMBER(INDIRECT("'"&H$6&"'!"&H$4&ROW()-31)))),"-",INDIRECT("'"&H$6&"'!"&H$4&ROW()-31))} -> - | I46: {=IF(OR(TRIM(INDIRECT("'"&I$6&"'!"&I$4&ROW()-31))="0",INDIRECT("'"&I$6&"'!"&I$4&ROW()-31)="",NOT(ISNUMBER(INDIRECT("'"&I$6&"'!"&I$4&ROW()-31)))),"-",INDIRECT("'"&I$6&"'!"&I$4&ROW()-31))} -> - | ... M46: {=IF(OR(TRIM(INDIRECT("'"&M$6&"'!"&M$4&ROW()-31))="0",INDIRECT("'"&M$6&"'!"&M$4&ROW()-31)="",NOT(ISNUMBER(INDIRECT("'"&M$6&"'!"&M$4&ROW()-31)))),"-",INDIRECT("'"&M$6&"'!"&M$4&ROW()-31))} -> - | N46: 0 | O46: 0
A47: ='Section-Category'!A84 -> Car Repair / Workshop | B47: {=IF(OR(TRIM(INDIRECT("'"&B$6&"'!"&B$4&ROW()-31))="0",INDIRECT("'"&B$6&"'!"&B$4&ROW()-31)="",NOT(ISNUMBER(INDIRECT("'"&B$6&"'!"&B$4&ROW()-31)))),"-",INDIRECT("'"&B$6&"'!"&B$4&ROW()-31))} -> - | C47: {=IF(OR(TRIM(INDIRECT("'"&C$6&"'!"&C$4&ROW()-31))="0",INDIRECT("'"&C$6&"'!"&C$4&ROW()-31)="",NOT(ISNUMBER(INDIRECT("'"&C$6&"'!"&C$4&ROW()-31)))),"-",INDIRECT("'"&C$6&"'!"&C$4&ROW()-31))} -> - | D47: {=IF(OR(TRIM(INDIRECT("'"&D$6&"'!"&D$4&ROW()-31))="0",INDIRECT("'"&D$6&"'!"&D$4&ROW()-31)="",NOT(ISNUMBER(INDIRECT("'"&D$6&"'!"&D$4&ROW()-31)))),"-",INDIRECT("'"&D$6&"'!"&D$4&ROW()-31))} -> - | E47: {=IF(OR(TRIM(INDIRECT("'"&E$6&"'!"&E$4&ROW()-31))="0",INDIRECT("'"&E$6&"'!"&E$4&ROW()-31)="",NOT(ISNUMBER(INDIRECT("'"&E$6&"'!"&E$4&ROW()-31)))),"-",INDIRECT("'"&E$6&"'!"&E$4&ROW()-31))} -> - | F47: {=IF(OR(TRIM(INDIRECT("'"&F$6&"'!"&F$4&ROW()-31))="0",INDIRECT("'"&F$6&"'!"&F$4&ROW()-31)="",NOT(ISNUMBER(INDIRECT("'"&F$6&"'!"&F$4&ROW()-31)))),"-",INDIRECT("'"&F$6&"'!"&F$4&ROW()-31))} -> - | G47: {=IF(OR(TRIM(INDIRECT("'"&G$6&"'!"&G$4&ROW()-31))="0",INDIRECT("'"&G$6&"'!"&G$4&ROW()-31)="",NOT(ISNUMBER(INDIRECT("'"&G$6&"'!"&G$4&ROW()-31)))),"-",INDIRECT("'"&G$6&"'!"&G$4&ROW()-31))} -> - | H47: {=IF(OR(TRIM(INDIRECT("'"&H$6&"'!"&H$4&ROW()-31))="0",INDIRECT("'"&H$6&"'!"&H$4&ROW()-31)="",NOT(ISNUMBER(INDIRECT("'"&H$6&"'!"&H$4&ROW()-31)))),"-",INDIRECT("'"&H$6&"'!"&H$4&ROW()-31))} -> - | I47: {=IF(OR(TRIM(INDIRECT("'"&I$6&"'!"&I$4&ROW()-31))="0",INDIRECT("'"&I$6&"'!"&I$4&ROW()-31)="",NOT(ISNUMBER(INDIRECT("'"&I$6&"'!"&I$4&ROW()-31)))),"-",INDIRECT("'"&I$6&"'!"&I$4&ROW()-31))} -> - | ... M47: {=IF(OR(TRIM(INDIRECT("'"&M$6&"'!"&M$4&ROW()-31))="0",INDIRECT("'"&M$6&"'!"&M$4&ROW()-31)="",NOT(ISNUMBER(INDIRECT("'"&M$6&"'!"&M$4&ROW()-31)))),"-",INDIRECT("'"&M$6&"'!"&M$4&ROW()-31))} -> - | N47: 0 | O47: 0
A48: ='Section-Category'!A85 -> Food | B48: {=IF(OR(TRIM(INDIRECT("'"&B$6&"'!"&B$4&ROW()-31))="0",INDIRECT("'"&B$6&"'!"&B$4&ROW()-31)="",NOT(ISNUMBER(INDIRECT("'"&B$6&"'!"&B$4&ROW()-31)))),"-",INDIRECT("'"&B$6&"'!"&B$4&ROW()-31))} -> - | C48: {=IF(OR(TRIM(INDIRECT("'"&C$6&"'!"&C$4&ROW()-31))="0",INDIRECT("'"&C$6&"'!"&C$4&ROW()-31)="",NOT(ISNUMBER(INDIRECT("'"&C$6&"'!"&C$4&ROW()-31)))),"-",INDIRECT("'"&C$6&"'!"&C$4&ROW()-31))} -> - | D48: {=IF(OR(TRIM(INDIRECT("'"&D$6&"'!"&D$4&ROW()-31))="0",INDIRECT("'"&D$6&"'!"&D$4&ROW()-31)="",NOT(ISNUMBER(INDIRECT("'"&D$6&"'!"&D$4&ROW()-31)))),"-",INDIRECT("'"&D$6&"'!"&D$4&ROW()-31))} -> - | E48: {=IF(OR(TRIM(INDIRECT("'"&E$6&"'!"&E$4&ROW()-31))="0",INDIRECT("'"&E$6&"'!"&E$4&ROW()-31)="",NOT(ISNUMBER(INDIRECT("'"&E$6&"'!"&E$4&ROW()-31)))),"-",INDIRECT("'"&E$6&"'!"&E$4&ROW()-31))} -> - | F48: {=IF(OR(TRIM(INDIRECT("'"&F$6&"'!"&F$4&ROW()-31))="0",INDIRECT("'"&F$6&"'!"&F$4&ROW()-31)="",NOT(ISNUMBER(INDIRECT("'"&F$6&"'!"&F$4&ROW()-31)))),"-",INDIRECT("'"&F$6&"'!"&F$4&ROW()-31))} -> - | G48: {=IF(OR(TRIM(INDIRECT("'"&G$6&"'!"&G$4&ROW()-31))="0",INDIRECT("'"&G$6&"'!"&G$4&ROW()-31)="",NOT(ISNUMBER(INDIRECT("'"&G$6&"'!"&G$4&ROW()-31)))),"-",INDIRECT("'"&G$6&"'!"&G$4&ROW()-31))} -> - | H48: {=IF(OR(TRIM(INDIRECT("'"&H$6&"'!"&H$4&ROW()-31))="0",INDIRECT("'"&H$6&"'!"&H$4&ROW()-31)="",NOT(ISNUMBER(INDIRECT("'"&H$6&"'!"&H$4&ROW()-31)))),"-",INDIRECT("'"&H$6&"'!"&H$4&ROW()-31))} -> - | I48: {=IF(OR(TRIM(INDIRECT("'"&I$6&"'!"&I$4&ROW()-31))="0",INDIRECT("'"&I$6&"'!"&I$4&ROW()-31)="",NOT(ISNUMBER(INDIRECT("'"&I$6&"'!"&I$4&ROW()-31)))),"-",INDIRECT("'"&I$6&"'!"&I$4&ROW()-31))} -> - | ... M48: {=IF(OR(TRIM(INDIRECT("'"&M$6&"'!"&M$4&ROW()-31))="0",INDIRECT("'"&M$6&"'!"&M$4&ROW()-31)="",NOT(ISNUMBER(INDIRECT("'"&M$6&"'!"&M$4&ROW()-31)))),"-",INDIRECT("'"&M$6&"'!"&M$4&ROW()-31))} -> - | N48: 0 | O48: 0
A49: ='Section-Category'!A86 -> Donation | B49: {=IF(OR(TRIM(INDIRECT("'"&B$6&"'!"&B$4&ROW()-31))="0",INDIRECT("'"&B$6&"'!"&B$4&ROW()-31)="",NOT(ISNUMBER(INDIRECT("'"&B$6&"'!"&B$4&ROW()-31)))),"-",INDIRECT("'"&B$6&"'!"&B$4&ROW()-31))} -> - | C49: {=IF(OR(TRIM(INDIRECT("'"&C$6&"'!"&C$4&ROW()-31))="0",INDIRECT("'"&C$6&"'!"&C$4&ROW()-31)="",NOT(ISNUMBER(INDIRECT("'"&C$6&"'!"&C$4&ROW()-31)))),"-",INDIRECT("'"&C$6&"'!"&C$4&ROW()-31))} -> - | D49: {=IF(OR(TRIM(INDIRECT("'"&D$6&"'!"&D$4&ROW()-31))="0",INDIRECT("'"&D$6&"'!"&D$4&ROW()-31)="",NOT(ISNUMBER(INDIRECT("'"&D$6&"'!"&D$4&ROW()-31)))),"-",INDIRECT("'"&D$6&"'!"&D$4&ROW()-31))} -> - | E49: {=IF(OR(TRIM(INDIRECT("'"&E$6&"'!"&E$4&ROW()-31))="0",INDIRECT("'"&E$6&"'!"&E$4&ROW()-31)="",NOT(ISNUMBER(INDIRECT("'"&E$6&"'!"&E$4&ROW()-31)))),"-",INDIRECT("'"&E$6&"'!"&E$4&ROW()-31))} -> - | F49: {=IF(OR(TRIM(INDIRECT("'"&F$6&"'!"&F$4&ROW()-31))="0",INDIRECT("'"&F$6&"'!"&F$4&ROW()-31)="",NOT(ISNUMBER(INDIRECT("'"&F$6&"'!"&F$4&ROW()-31)))),"-",INDIRECT("'"&F$6&"'!"&F$4&ROW()-31))} -> - | G49: {=IF(OR(TRIM(INDIRECT("'"&G$6&"'!"&G$4&ROW()-31))="0",INDIRECT("'"&G$6&"'!"&G$4&ROW()-31)="",NOT(ISNUMBER(INDIRECT("'"&G$6&"'!"&G$4&ROW()-31)))),"-",INDIRECT("'"&G$6&"'!"&G$4&ROW()-31))} -> - | H49: {=IF(OR(TRIM(INDIRECT("'"&H$6&"'!"&H$4&ROW()-31))="0",INDIRECT("'"&H$6&"'!"&H$4&ROW()-31)="",NOT(ISNUMBER(INDIRECT("'"&H$6&"'!"&H$4&ROW()-31)))),"-",INDIRECT("'"&H$6&"'!"&H$4&ROW()-31))} -> - | I49: {=IF(OR(TRIM(INDIRECT("'"&I$6&"'!"&I$4&ROW()-31))="0",INDIRECT("'"&I$6&"'!"&I$4&ROW()-31)="",NOT(ISNUMBER(INDIRECT("'"&I$6&"'!"&I$4&ROW()-31)))),"-",INDIRECT("'"&I$6&"'!"&I$4&ROW()-31))} -> - | ... M49: {=IF(OR(TRIM(INDIRECT("'"&M$6&"'!"&M$4&ROW()-31))="0",INDIRECT("'"&M$6&"'!"&M$4&ROW()-31)="",NOT(ISNUMBER(INDIRECT("'"&M$6&"'!"&M$4&ROW()-31)))),"-",INDIRECT("'"&M$6&"'!"&M$4&ROW()-31))} -> - | N49: 0 | O49: 0
A50: ='Section-Category'!A87 -> Medical | B50: {=IF(OR(TRIM(INDIRECT("'"&B$6&"'!"&B$4&ROW()-31))="0",INDIRECT("'"&B$6&"'!"&B$4&ROW()-31)="",NOT(ISNUMBER(INDIRECT("'"&B$6&"'!"&B$4&ROW()-31)))),"-",INDIRECT("'"&B$6&"'!"&B$4&ROW()-31))} -> - | C50: {=IF(OR(TRIM(INDIRECT("'"&C$6&"'!"&C$4&ROW()-31))="0",INDIRECT("'"&C$6&"'!"&C$4&ROW()-31)="",NOT(ISNUMBER(INDIRECT("'"&C$6&"'!"&C$4&ROW()-31)))),"-",INDIRECT("'"&C$6&"'!"&C$4&ROW()-31))} -> - | D50: {=IF(OR(TRIM(INDIRECT("'"&D$6&"'!"&D$4&ROW()-31))="0",INDIRECT("'"&D$6&"'!"&D$4&ROW()-31)="",NOT(ISNUMBER(INDIRECT("'"&D$6&"'!"&D$4&ROW()-31)))),"-",INDIRECT("'"&D$6&"'!"&D$4&ROW()-31))} -> - | E50: {=IF(OR(TRIM(INDIRECT("'"&E$6&"'!"&E$4&ROW()-31))="0",INDIRECT("'"&E$6&"'!"&E$4&ROW()-31)="",NOT(ISNUMBER(INDIRECT("'"&E$6&"'!"&E$4&ROW()-31)))),"-",INDIRECT("'"&E$6&"'!"&E$4&ROW()-31))} -> - | F50: {=IF(OR(TRIM(INDIRECT("'"&F$6&"'!"&F$4&ROW()-31))="0",INDIRECT("'"&F$6&"'!"&F$4&ROW()-31)="",NOT(ISNUMBER(INDIRECT("'"&F$6&"'!"&F$4&ROW()-31)))),"-",INDIRECT("'"&F$6&"'!"&F$4&ROW()-31))} -> - | G50: {=IF(OR(TRIM(INDIRECT("'"&G$6&"'!"&G$4&ROW()-31))="0",INDIRECT("'"&G$6&"'!"&G$4&ROW()-31)="",NOT(ISNUMBER(INDIRECT("'"&G$6&"'!"&G$4&ROW()-31)))),"-",INDIRECT("'"&G$6&"'!"&G$4&ROW()-31))} -> - | H50: {=IF(OR(TRIM(INDIRECT("'"&H$6&"'!"&H$4&ROW()-31))="0",INDIRECT("'"&H$6&"'!"&H$4&ROW()-31)="",NOT(ISNUMBER(INDIRECT("'"&H$6&"'!"&H$4&ROW()-31)))),"-",INDIRECT("'"&H$6&"'!"&H$4&ROW()-31))} -> - | I50: {=IF(OR(TRIM(INDIRECT("'"&I$6&"'!"&I$4&ROW()-31))="0",INDIRECT("'"&I$6&"'!"&I$4&ROW()-31)="",NOT(ISNUMBER(INDIRECT("'"&I$6&"'!"&I$4&ROW()-31)))),"-",INDIRECT("'"&I$6&"'!"&I$4&ROW()-31))} -> - | ... M50: {=IF(OR(TRIM(INDIRECT("'"&M$6&"'!"&M$4&ROW()-31))="0",INDIRECT("'"&M$6&"'!"&M$4&ROW()-31)="",NOT(ISNUMBER(INDIRECT("'"&M$6&"'!"&M$4&ROW()-31)))),"-",INDIRECT("'"&M$6&"'!"&M$4&ROW()-31))} -> - | N50: 0 | O50: 0
A51: ='Section-Category'!A88 -> Donation | B51: {=IF(OR(TRIM(INDIRECT("'"&B$6&"'!"&B$4&ROW()-31))="0",INDIRECT("'"&B$6&"'!"&B$4&ROW()-31)="",NOT(ISNUMBER(INDIRECT("'"&B$6&"'!"&B$4&ROW()-31)))),"-",INDIRECT("'"&B$6&"'!"&B$4&ROW()-31))} -> - | C51: {=IF(OR(TRIM(INDIRECT("'"&C$6&"'!"&C$4&ROW()-31))="0",INDIRECT("'"&C$6&"'!"&C$4&ROW()-31)="",NOT(ISNUMBER(INDIRECT("'"&C$6&"'!"&C$4&ROW()-31)))),"-",INDIRECT("'"&C$6&"'!"&C$4&ROW()-31))} -> - | D51: {=IF(OR(TRIM(INDIRECT("'"&D$6&"'!"&D$4&ROW()-31))="0",INDIRECT("'"&D$6&"'!"&D$4&ROW()-31)="",NOT(ISNUMBER(INDIRECT("'"&D$6&"'!"&D$4&ROW()-31)))),"-",INDIRECT("'"&D$6&"'!"&D$4&ROW()-31))} -> - | E51: {=IF(OR(TRIM(INDIRECT("'"&E$6&"'!"&E$4&ROW()-31))="0",INDIRECT("'"&E$6&"'!"&E$4&ROW()-31)="",NOT(ISNUMBER(INDIRECT("'"&E$6&"'!"&E$4&ROW()-31)))),"-",INDIRECT("'"&E$6&"'!"&E$4&ROW()-31))} -> - | F51: {=IF(OR(TRIM(INDIRECT("'"&F$6&"'!"&F$4&ROW()-31))="0",INDIRECT("'"&F$6&"'!"&F$4&ROW()-31)="",NOT(ISNUMBER(INDIRECT("'"&F$6&"'!"&F$4&ROW()-31)))),"-",INDIRECT("'"&F$6&"'!"&F$4&ROW()-31))} -> - | G51: {=IF(OR(TRIM(INDIRECT("'"&G$6&"'!"&G$4&ROW()-31))="0",INDIRECT("'"&G$6&"'!"&G$4&ROW()-31)="",NOT(ISNUMBER(INDIRECT("'"&G$6&"'!"&G$4&ROW()-31)))),"-",INDIRECT("'"&G$6&"'!"&G$4&ROW()-31))} -> - | H51: {=IF(OR(TRIM(INDIRECT("'"&H$6&"'!"&H$4&ROW()-31))="0",INDIRECT("'"&H$6&"'!"&H$4&ROW()-31)="",NOT(ISNUMBER(INDIRECT("'"&H$6&"'!"&H$4&ROW()-31)))),"-",INDIRECT("'"&H$6&"'!"&H$4&ROW()-31))} -> - | I51: {=IF(OR(TRIM(INDIRECT("'"&I$6&"'!"&I$4&ROW()-31))="0",INDIRECT("'"&I$6&"'!"&I$4&ROW()-31)="",NOT(ISNUMBER(INDIRECT("'"&I$6&"'!"&I$4&ROW()-31)))),"-",INDIRECT("'"&I$6&"'!"&I$4&ROW()-31))} -> - | ... M51: {=IF(OR(TRIM(INDIRECT("'"&M$6&"'!"&M$4&ROW()-31))="0",INDIRECT("'"&M$6&"'!"&M$4&ROW()-31)="",NOT(ISNUMBER(INDIRECT("'"&M$6&"'!"&M$4&ROW()-31)))),"-",INDIRECT("'"&M$6&"'!"&M$4&ROW()-31))} -> - | N51: 0 | O51: 0
A52: ='Section-Category'!A89 -> Pocket Money Husband | B52: {=IF(OR(TRIM(INDIRECT("'"&B$6&"'!"&B$4&ROW()-31))="0",INDIRECT("'"&B$6&"'!"&B$4&ROW()-31)="",NOT(ISNUMBER(INDIRECT("'"&B$6&"'!"&B$4&ROW()-31)))),"-",INDIRECT("'"&B$6&"'!"&B$4&ROW()-31))} -> - | C52: {=IF(OR(TRIM(INDIRECT("'"&C$6&"'!"&C$4&ROW()-31))="0",INDIRECT("'"&C$6&"'!"&C$4&ROW()-31)="",NOT(ISNUMBER(INDIRECT("'"&C$6&"'!"&C$4&ROW()-31)))),"-",INDIRECT("'"&C$6&"'!"&C$4&ROW()-31))} -> - | D52: {=IF(OR(TRIM(INDIRECT("'"&D$6&"'!"&D$4&ROW()-31))="0",INDIRECT("'"&D$6&"'!"&D$4&ROW()-31)="",NOT(ISNUMBER(INDIRECT("'"&D$6&"'!"&D$4&ROW()-31)))),"-",INDIRECT("'"&D$6&"'!"&D$4&ROW()-31))} -> - | E52: {=IF(OR(TRIM(INDIRECT("'"&E$6&"'!"&E$4&ROW()-31))="0",INDIRECT("'"&E$6&"'!"&E$4&ROW()-31)="",NOT(ISNUMBER(INDIRECT("'"&E$6&"'!"&E$4&ROW()-31)))),"-",INDIRECT("'"&E$6&"'!"&E$4&ROW()-31))} -> - | F52: {=IF(OR(TRIM(INDIRECT("'"&F$6&"'!"&F$4&ROW()-31))="0",INDIRECT("'"&F$6&"'!"&F$4&ROW()-31)="",NOT(ISNUMBER(INDIRECT("'"&F$6&"'!"&F$4&ROW()-31)))),"-",INDIRECT("'"&F$6&"'!"&F$4&ROW()-31))} -> - | G52: {=IF(OR(TRIM(INDIRECT("'"&G$6&"'!"&G$4&ROW()-31))="0",INDIRECT("'"&G$6&"'!"&G$4&ROW()-31)="",NOT(ISNUMBER(INDIRECT("'"&G$6&"'!"&G$4&ROW()-31)))),"-",INDIRECT("'"&G$6&"'!"&G$4&ROW()-31))} -> - | H52: {=IF(OR(TRIM(INDIRECT("'"&H$6&"'!"&H$4&ROW()-31))="0",INDIRECT("'"&H$6&"'!"&H$4&ROW()-31)="",NOT(ISNUMBER(INDIRECT("'"&H$6&"'!"&H$4&ROW()-31)))),"-",INDIRECT("'"&H$6&"'!"&H$4&ROW()-31))} -> - | I52: {=IF(OR(TRIM(INDIRECT("'"&I$6&"'!"&I$4&ROW()-31))="0",INDIRECT("'"&I$6&"'!"&I$4&ROW()-31)="",NOT(ISNUMBER(INDIRECT("'"&I$6&"'!"&I$4&ROW()-31)))),"-",INDIRECT("'"&I$6&"'!"&I$4&ROW()-31))} -> - | ... M52: {=IF(OR(TRIM(INDIRECT("'"&M$6&"'!"&M$4&ROW()-31))="0",INDIRECT("'"&M$6&"'!"&M$4&ROW()-31)="",NOT(ISNUMBER(INDIRECT("'"&M$6&"'!"&M$4&ROW()-31)))),"-",INDIRECT("'"&M$6&"'!"&M$4&ROW()-31))} -> - | N52: 0 | O52: 0
A53: ='Section-Category'!A90 -> Other | B53: {=IF(OR(TRIM(INDIRECT("'"&B$6&"'!"&B$4&ROW()-31))="0",INDIRECT("'"&B$6&"'!"&B$4&ROW()-31)="",NOT(ISNUMBER(INDIRECT("'"&B$6&"'!"&B$4&ROW()-31)))),"-",INDIRECT("'"&B$6&"'!"&B$4&ROW()-31))} -> - | C53: {=IF(OR(TRIM(INDIRECT("'"&C$6&"'!"&C$4&ROW()-31))="0",INDIRECT("'"&C$6&"'!"&C$4&ROW()-31)="",NOT(ISNUMBER(INDIRECT("'"&C$6&"'!"&C$4&ROW()-31)))),"-",INDIRECT("'"&C$6&"'!"&C$4&ROW()-31))} -> - | D53: {=IF(OR(TRIM(INDIRECT("'"&D$6&"'!"&D$4&ROW()-31))="0",INDIRECT("'"&D$6&"'!"&D$4&ROW()-31)="",NOT(ISNUMBER(INDIRECT("'"&D$6&"'!"&D$4&ROW()-31)))),"-",INDIRECT("'"&D$6&"'!"&D$4&ROW()-31))} -> - | E53: {=IF(OR(TRIM(INDIRECT("'"&E$6&"'!"&E$4&ROW()-31))="0",INDIRECT("'"&E$6&"'!"&E$4&ROW()-31)="",NOT(ISNUMBER(INDIRECT("'"&E$6&"'!"&E$4&ROW()-31)))),"-",INDIRECT("'"&E$6&"'!"&E$4&ROW()-31))} -> - | F53: {=IF(OR(TRIM(INDIRECT("'"&F$6&"'!"&F$4&ROW()-31))="0",INDIRECT("'"&F$6&"'!"&F$4&ROW()-31)="",NOT(ISNUMBER(INDIRECT("'"&F$6&"'!"&F$4&ROW()-31)))),"-",INDIRECT("'"&F$6&"'!"&F$4&ROW()-31))} -> - | G53: {=IF(OR(TRIM(INDIRECT("'"&G$6&"'!"&G$4&ROW()-31))="0",INDIRECT("'"&G$6&"'!"&G$4&ROW()-31)="",NOT(ISNUMBER(INDIRECT("'"&G$6&"'!"&G$4&ROW()-31)))),"-",INDIRECT("'"&G$6&"'!"&G$4&ROW()-31))} -> - | H53: {=IF(OR(TRIM(INDIRECT("'"&H$6&"'!"&H$4&ROW()-31))="0",INDIRECT("'"&H$6&"'!"&H$4&ROW()-31)="",NOT(ISNUMBER(INDIRECT("'"&H$6&"'!"&H$4&ROW()-31)))),"-",INDIRECT("'"&H$6&"'!"&H$4&ROW()-31))} -> - | I53: {=IF(OR(TRIM(INDIRECT("'"&I$6&"'!"&I$4&ROW()-31))="0",INDIRECT("'"&I$6&"'!"&I$4&ROW()-31)="",NOT(ISNUMBER(INDIRECT("'"&I$6&"'!"&I$4&ROW()-31)))),"-",INDIRECT("'"&I$6&"'!"&I$4&ROW()-31))} -> - | ... M53: {=IF(OR(TRIM(INDIRECT("'"&M$6&"'!"&M$4&ROW()-31))="0",INDIRECT("'"&M$6&"'!"&M$4&ROW()-31)="",NOT(ISNUMBER(INDIRECT("'"&M$6&"'!"&M$4&ROW()-31)))),"-",INDIRECT("'"&M$6&"'!"&M$4&ROW()-31))} -> - | N53: 0 | O53: 0
A54: ='Section-Category'!A91 -> Total Petty Cash Used | B54: =SUM(B46:B53) -> 0 | C54: =SUM(C46:C53) -> 0 | D54: =SUM(D46:D53) -> 0 | E54: =SUM(E46:E53) -> 0 | F54: =SUM(F46:F53) -> 0 | G54: =SUM(G46:G53) -> 0 | H54: =SUM(H46:H53) -> 0 | I54: =SUM(I46:I53) -> 0 | ... O54: =SUM(O46:O53) -> 0
A55: ='Section-Category'!A92 -> % of Total Petty Cash | B55: =IF(B$11=0," - ",B54/B$11) -> - | C55: =IF(C$11=0," - ",C54/C$11) -> - | D55: =IF(D$11=0," - ",D54/D$11) -> - | E55: =IF(E$11=0," - ",E54/E$11) -> - | F55: =IF(F$11=0," - ",F54/F$11) -> - | G55: =IF(G$11=0," - ",G54/G$11) -> - | H55: =IF(H$11=0," - ",H54/H$11) -> - | I55: =IF(I$11=0," - ",I54/I$11) -> - | ... O55: =IF(O$11=0," - ",O54/O$11) -> -
A57: ='Section-Category'!A11 -> SAVINGS EXPENSE | B57: =B$6 -> Jan | C57: =C$6 -> Feb | D57: =D$6 -> Mar | E57: =E$6 -> Apr | F57: =F$6 -> May | G57: =G$6 -> Jun | H57: =H$6 -> Jul | I57: =I$6 -> Aug | ... M57: =M$6 -> Dec | N57: Total | O57: Avg
...

Sheet Jan
A1: =MID(CELL("filename",A1),FIND("]",CELL("filename",A1))+1,255) -> Jan | B1: =Budget!D1 -> 2026
A2: Summary/Date | B2: ='Section-Category'!D6 -> 46023 | C2: ='Section-Category'!E6 -> 46024 | D2: ='Section-Category'!F6 -> 46025 | E2: ='Section-Category'!G6 -> 46026 | F2: ='Section-Category'!H6 -> 46027 | G2: ='Section-Category'!I6 -> 46028 | H2: ='Section-Category'!J6 -> 46029 | I2: ='Section-Category'!K6 -> 46030 | ... AF2: ='Section-Category'!AH6 -> 46053 | AG2: Total Sum
A4: INCOME | AG4: Total
A5: Wages & Tips | AG5: =SUM(B5:AF5) -> 0
A6: Interest Income | AG6: =SUM(B6:AF6) -> 0
A7: Dividends | AG7: =SUM(B7:AF7) -> 0
A8: Gifts Received | AG8: =SUM(B8:AF8) -> 0
A9: Refunds/Reimbursements | AG9: =SUM(B9:AF9) -> 0
A10: Other | AG10: =SUM(B10:AF10) -> 0
A11: Transfer From Savings | AG11: =SUM(B11:AF11) -> 0
A12: ='Section-Category'!A9 -> Total INCOME | B12: =SUM(B5:B11) -> 0 | C12: =SUM(C5:C11) -> 0 | D12: =SUM(D5:D11) -> 0 | E12: =SUM(E5:E11) -> 0 | F12: =SUM(F5:F11) -> 0 | G12: =SUM(G5:G11) -> 0 | H12: =SUM(H5:H11) -> 0 | I12: =SUM(I5:I11) -> 0 | ... AD12: =SUM(AD5:AD11) -> 0 | AF12: =SUM(AF5:AF11) -> 0 | AG12: =SUM(AG5:AG11) -> 0
A14: ='Section-Category'!A82 -> Petty Cash Used | AG14: Total
A15: ='Section-Category'!A83 -> Pocket Money Wife | AG15: =SUM(B15:AF15) -> 0
A16: ='Section-Category'!A84 -> Car Repair / Workshop | AG16: =SUM(B16:AF16) -> 0
A17: ='Section-Category'!A85 -> Food | AG17: =SUM(B17:AF17) -> 0
A18: ='Section-Category'!A86 -> Donation | AG18: =SUM(B18:AF18) -> 0
A19: Eidi | AG19: =SUM(B19:AF19) -> 0
A20: ='Section-Category'!A88 -> Donation | AG20: =SUM(B20:AF20) -> 0
A21: ='Section-Category'!A89 -> Pocket Money Husband | AG21: =SUM(B21:AF21) -> 0
A22: ='Section-Category'!A90 -> Other | AG22: =SUM(B22:AF22) -> 0
A23: ='Section-Category'!A91 -> Total Petty Cash Used | B23: =SUM(B15:B22) -> 0 | C23: =SUM(C15:C22) -> 0 | D23: =SUM(D15:D22) -> 0 | E23: =SUM(E15:E22) -> 0 | F23: =SUM(F15:F22) -> 0 | G23: =SUM(G15:G22) -> 0 | H23: =SUM(H15:H22) -> 0 | I23: =SUM(I15:I22) -> 0 | ... AD23: =SUM(AD15:AD22) -> 0 | AF23: =SUM(AF15:AF22) -> 0 | AG23: =SUM(AG15:AG22) -> 0
A25: ='Section-Category'!A11 -> SAVINGS EXPENSE | AG25: Total
A26: ='Section-Category'!A12 -> Emergency Fund | AG26: =SUM(B26:AF26) -> 0
A27: ='Section-Category'!A13 -> Investments | AG27: =SUM(B27:AF27) -> 0
A28: ='Section-Category'!A14 -> Pocket Money Wife | AG28: =SUM(B28:AF28) -> 0
A29: ='Section-Category'!A15 -> <Name-Of-Entry> | AG29: =SUM(B29:AF29) -> 0
A30: ='Section-Category'!A16 -> <Name-Of-Entry> | AG30: =SUM(B30:AF30) -> 0
A31: ='Section-Category'!A17 -> Total SAVINGS EXPENSE | B31: =SUM(B26:B30) -> 0 | C31: =SUM(C26:C30) -> 0 | D31: =SUM(D26:D30) -> 0 | E31: =SUM(E26:E30) -> 0 | F31: =SUM(F26:F30) -> 0 | G31: =SUM(G26:G30) -> 0 | H31: =SUM(H26:H30) -> 0 | I31: =SUM(I26:I30) -> 0 | ... AD31: =SUM(AD26:AD30) -> 0 | AF31: =SUM(AF26:AF30) -> 0 | AG31: =SUM(AG26:AG30) -> 0
A33: ='Section-Category'!A20 -> HOME EXPENSES | AG33: Total
A34: ='Section-Category'!A21 -> Mortgage/Rent | AG34: =SUM(B34:AF34) -> 0
A35: ='Section-Category'!A22 -> Electricity | AG35: =SUM(B35:AF35) -> 0
A36: ='Section-Category'!A23 -> Gas/Oil | AG36: =SUM(B36:AF36) -> 0
A37: ='Section-Category'!A24 -> Water/Sewer/Trash | AG37: =SUM(B37:AF37) -> 0
A38: ='Section-Category'!A25 -> Phone | AG38: =SUM(B38:AF38) -> 0
A39: ='Section-Category'!A26 -> Cable/Satellite | AG39: =SUM(B39:AF39) -> 0
A40: ='Section-Category'!A27 -> Internet | AG40: =SUM(B40:AF40) -> 0
A41: ='Section-Category'!A28 -> Furnishings/Appliances | AG41: =SUM(B41:AF41) -> 0
A42: ='Section-Category'!A29 -> Lawn/Garden | AG42: =SUM(B42:AF42) -> 0
A43: ='Section-Category'!A30 -> Home Supplies | AG43: =SUM(B43:AF43) -> 0
A44: ='Section-Category'!A31 -> Maintenance | AG44: =SUM(B44:AF44) -> 0
...

Sheet Feb
A1: =MID(CELL("filename",A1),FIND("]",CELL("filename",A1))+1,255) -> Feb | B1: =Budget!D1 -> 2026
A2: Summary/Date | B2: ='Section-Category'!D7 -> 46054 | C2: ='Section-Category'!E7 -> 46055 | D2: ='Section-Category'!F7 -> 46056 | E2: ='Section-Category'!G7 -> 46057 | F2: ='Section-Category'!H7 -> 46058 | G2: ='Section-Category'!I7 -> 46059 | H2: ='Section-Category'!J7 -> 46060 | I2: ='Section-Category'!K7 -> 46061 | ... AE2: ='Section-Category'!AG7 -> # | AF2: Total Sum
A4: INCOME | AF4: Total
A5: Wages & Tips | AF5: =SUM(B5:AC5) -> 0
A6: Interest Income | AF6: =SUM(B6:AC6) -> 0
A7: Dividends | AF7: =SUM(B7:AC7) -> 0
A8: Gifts Received | AF8: =SUM(B8:AC8) -> 0
A9: Refunds/Reimbursements | AF9: =SUM(B9:AC9) -> 0
A10: Other | AF10: =SUM(B10:AC10) -> 0
A11: Transfer From Savings | AF11: =SUM(B11:AC11) -> 0
A12: ='Section-Category'!A9 -> Total INCOME | B12: =SUM(B5:B11) -> 0 | C12: =SUM(C5:C11) -> 0 | D12: =SUM(D5:D11) -> 0 | E12: =SUM(E5:E11) -> 0 | F12: =SUM(F5:F11) -> 0 | G12: =SUM(G5:G11) -> 0 | H12: =SUM(H5:H11) -> 0 | I12: =SUM(I5:I11) -> 0 | ... AC12: =SUM(AC5:AC11) -> 0 | AF12: =SUM(AF5:AF11) -> 0
A14: ='Section-Category'!A82 -> Petty Cash Used | AF14: Total
A15: ='Section-Category'!A83 -> Pocket Money Wife | AF15: =SUM(B15:AC15) -> 0
A16: ='Section-Category'!A84 -> Car Repair / Workshop | AF16: =SUM(B16:AC16) -> 0
A17: ='Section-Category'!A85 -> Food | AF17: =SUM(B17:AC17) -> 0
A18: ='Section-Category'!A86 -> Donation | AF18: =SUM(B18:AC18) -> 0
A19: Eidi | AF19: =SUM(B19:AC19) -> 0
A20: ='Section-Category'!A88 -> Donation | AF20: =SUM(B20:AC20) -> 0
A21: ='Section-Category'!A89 -> Pocket Money Husband | AF21: =SUM(B21:AC21) -> 0
A22: ='Section-Category'!A90 -> Other | AF22: =SUM(B22:AC22) -> 0
A23: ='Section-Category'!A91 -> Total Petty Cash Used | B23: =SUM(B15:B22) -> 0 | C23: =SUM(C15:C22) -> 0 | D23: =SUM(D15:D22) -> 0 | E23: =SUM(E15:E22) -> 0 | F23: =SUM(F15:F22) -> 0 | G23: =SUM(G15:G22) -> 0 | H23: =SUM(H15:H22) -> 0 | I23: =SUM(I15:I22) -> 0 | ... AC23: =SUM(AC15:AC22) -> 0 | AF23: =SUM(AF15:AF22) -> 0
A25: ='Section-Category'!A11 -> SAVINGS EXPENSE | AF25: Total
A26: ='Section-Category'!A12 -> Emergency Fund | AF26: =SUM(B26:AC26) -> 0
A27: ='Section-Category'!A13 -> Investments | AF27: =SUM(B27:AC27) -> 0
A28: ='Section-Category'!A14 -> Pocket Money Wife | AF28: =SUM(B28:AC28) -> 0
A29: ='Section-Category'!A15 -> <Name-Of-Entry> | AF29: =SUM(B29:AC29) -> 0
A30: ='Section-Category'!A16 -> <Name-Of-Entry> | AF30: =SUM(B30:AC30) -> 0
A31: ='Section-Category'!A17 -> Total SAVINGS EXPENSE | B31: =SUM(B26:B30) -> 0 | C31: =SUM(C26:C30) -> 0 | D31: =SUM(D26:D30) -> 0 | E31: =SUM(E26:E30) -> 0 | F31: =SUM(F26:F30) -> 0 | G31: =SUM(G26:G30) -> 0 | H31: =SUM(H26:H30) -> 0 | I31: =SUM(I26:I30) -> 0 | ... AC31: =SUM(AC26:AC30) -> 0 | AF31: =SUM(AF26:AF30) -> 0
A33: ='Section-Category'!A20 -> HOME EXPENSES | AF33: Total
A34: ='Section-Category'!A21 -> Mortgage/Rent | AF34: =SUM(B34:AC34) -> 0
A35: ='Section-Category'!A22 -> Electricity | AF35: =SUM(B35:AC35) -> 0
A36: ='Section-Category'!A23 -> Gas/Oil | AF36: =SUM(B36:AC36) -> 0
A37: ='Section-Category'!A24 -> Water/Sewer/Trash | AF37: =SUM(B37:AC37) -> 0
A38: ='Section-Category'!A25 -> Phone | AF38: =SUM(B38:AC38) -> 0
A39: ='Section-Category'!A26 -> Cable/Satellite | AF39: =SUM(B39:AC39) -> 0
A40: ='Section-Category'!A27 -> Internet | AF40: =SUM(B40:AC40) -> 0
A41: ='Section-Category'!A28 -> Furnishings/Appliances | AF41: =SUM(B41:AC41) -> 0
A42: ='Section-Category'!A29 -> Lawn/Garden | AF42: =SUM(B42:AC42) -> 0
A43: ='Section-Category'!A30 -> Home Supplies | AF43: =SUM(B43:AC43) -> 0
A44: ='Section-Category'!A31 -> Maintenance | AF44: =SUM(B44:AC44) -> 0
...

Sheet Mar
A1: =MID(CELL("filename",A1),FIND("]",CELL("filename",A1))+1,255) -> Mar | B1: =Budget!D1 -> 2026
A2: Summary/Date | B2: ='Section-Category'!D8 -> 46082 | C2: ='Section-Category'!E8 -> 46083 | D2: ='Section-Category'!F8 -> 46084 | E2: ='Section-Category'!G8 -> 46085 | F2: ='Section-Category'!H8 -> 46086 | G2: ='Section-Category'!I8 -> 46087 | H2: ='Section-Category'!J8 -> 46088 | I2: ='Section-Category'!K8 -> 46089 | ... AF2: ='Section-Category'!AH8 -> 46112 | AG2: Total Sum
A4: INCOME | AG4: Total
A5: Wages & Tips | AG5: =SUM(B5:AF5) -> 0
A6: Interest Income | AG6: =SUM(B6:AF6) -> 0
A7: Dividends | AG7: =SUM(B7:AF7) -> 0
A8: Gifts Received | AG8: =SUM(B8:AF8) -> 0
A9: Refunds/Reimbursements | AG9: =SUM(B9:AF9) -> 0
A10: Other | AG10: =SUM(B10:AF10) -> 0
A11: Transfer From Savings | AG11: =SUM(B11:AF11) -> 0
A12: ='Section-Category'!A9 -> Total INCOME | B12: =SUM(B5:B11) -> 0 | C12: =SUM(C5:C11) -> 0 | D12: =SUM(D5:D11) -> 0 | E12: =SUM(E5:E11) -> 0 | F12: =SUM(F5:F11) -> 0 | G12: =SUM(G5:G11) -> 0 | H12: =SUM(H5:H11) -> 0 | I12: =SUM(I5:I11) -> 0 | ... AD12: =SUM(AD5:AD11) -> 0 | AF12: =SUM(AF5:AF11) -> 0 | AG12: =SUM(AG5:AG11) -> 0
A14: ='Section-Category'!A82 -> Petty Cash Used | AG14: Total
A15: ='Section-Category'!A83 -> Pocket Money Wife | AG15: =SUM(B15:AF15) -> 0
A16: ='Section-Category'!A84 -> Car Repair / Workshop | AG16: =SUM(B16:AF16) -> 0
A17: ='Section-Category'!A85 -> Food | AG17: =SUM(B17:AF17) -> 0
A18: ='Section-Category'!A86 -> Donation | AG18: =SUM(B18:AF18) -> 0
A19: Eidi | AG19: =SUM(B19:AF19) -> 0
A20: ='Section-Category'!A88 -> Donation | AG20: =SUM(B20:AF20) -> 0
A21: ='Section-Category'!A89 -> Pocket Money Husband | AG21: =SUM(B21:AF21) -> 0
A22: ='Section-Category'!A90 -> Other | AG22: =SUM(B22:AF22) -> 0
A23: ='Section-Category'!A91 -> Total Petty Cash Used | B23: =SUM(B15:B22) -> 0 | C23: =SUM(C15:C22) -> 0 | D23: =SUM(D15:D22) -> 0 | E23: =SUM(E15:E22) -> 0 | F23: =SUM(F15:F22) -> 0 | G23: =SUM(G15:G22) -> 0 | H23: =SUM(H15:H22) -> 0 | I23: =SUM(I15:I22) -> 0 | ... AD23: =SUM(AD15:AD22) -> 0 | AF23: =SUM(AF15:AF22) -> 0 | AG23: =SUM(AG15:AG22) -> 0
A25: ='Section-Category'!A11 -> SAVINGS EXPENSE | AG25: Total
A26: ='Section-Category'!A12 -> Emergency Fund | AG26: =SUM(B26:AF26) -> 0
A27: ='Section-Category'!A13 -> Investments | AG27: =SUM(B27:AF27) -> 0
A28: ='Section-Category'!A14 -> Pocket Money Wife | AG28: =SUM(B28:AF28) -> 0
A29: ='Section-Category'!A15 -> <Name-Of-Entry> | AG29: =SUM(B29:AF29) -> 0
A30: ='Section-Category'!A16 -> <Name-Of-Entry> | AG30: =SUM(B30:AF30) -> 0
A31: ='Section-Category'!A17 -> Total SAVINGS EXPENSE | B31: =SUM(B26:B30) -> 0 | C31: =SUM(C26:C30) -> 0 | D31: =SUM(D26:D30) -> 0 | E31: =SUM(E26:E30) -> 0 | F31: =SUM(F26:F30) -> 0 | G31: =SUM(G26:G30) -> 0 | H31: =SUM(H26:H30) -> 0 | I31: =SUM(I26:I30) -> 0 | ... AD31: =SUM(AD26:AD30) -> 0 | AF31: =SUM(AF26:AF30) -> 0 | AG31: =SUM(AG26:AG30) -> 0
A33: ='Section-Category'!A20 -> HOME EXPENSES | AG33: Total
A34: ='Section-Category'!A21 -> Mortgage/Rent | AG34: =SUM(B34:AF34) -> 0
A35: ='Section-Category'!A22 -> Electricity | AG35: =SUM(B35:AF35) -> 0
A36: ='Section-Category'!A23 -> Gas/Oil | AG36: =SUM(B36:AF36) -> 0
A37: ='Section-Category'!A24 -> Water/Sewer/Trash | AG37: =SUM(B37:AF37) -> 0
A38: ='Section-Category'!A25 -> Phone | AG38: =SUM(B38:AF38) -> 0
A39: ='Section-Category'!A26 -> Cable/Satellite | AG39: =SUM(B39:AF39) -> 0
A40: ='Section-Category'!A27 -> Internet | AG40: =SUM(B40:AF40) -> 0
A41: ='Section-Category'!A28 -> Furnishings/Appliances | AG41: =SUM(B41:AF41) -> 0
A42: ='Section-Category'!A29 -> Lawn/Garden | AG42: =SUM(B42:AF42) -> 0
A43: ='Section-Category'!A30 -> Home Supplies | AG43: =SUM(B43:AF43) -> 0
A44: ='Section-Category'!A31 -> Maintenance | AG44: =SUM(B44:AF44) -> 0
...

Sheet Apr
A1: =MID(CELL("filename",A1),FIND("]",CELL("filename",A1))+1,255) -> Apr | B1: =Budget!D1 -> 2026
A2: Summary/Date | B2: ='Section-Category'!D9 -> 46113 | C2: ='Section-Category'!E9 -> 46114 | D2: ='Section-Category'!F9 -> 46115 | E2: ='Section-Category'!G9 -> 46116 | F2: ='Section-Category'!H9 -> 46117 | G2: ='Section-Category'!I9 -> 46118 | H2: ='Section-Category'!J9 -> 46119 | I2: ='Section-Category'!K9 -> 46120 | ... AE2: ='Section-Category'!AG9 -> 46142 | AF2: Total Sum
A4: INCOME | AF4: Total
A5: Wages & Tips | AF5: =SUM(B5:AE5) -> 0
A6: Interest Income | AF6: =SUM(B6:AE6) -> 0
A7: Dividends | AF7: =SUM(B7:AE7) -> 0
A8: Gifts Received | AF8: =SUM(B8:AE8) -> 0
A9: Refunds/Reimbursements | AF9: =SUM(B9:AE9) -> 0
A10: Other | AF10: =SUM(B10:AE10) -> 0
A11: Transfer From Savings | AF11: =SUM(B11:AE11) -> 0
A12: ='Section-Category'!A9 -> Total INCOME | B12: =SUM(B5:B11) -> 0 | C12: =SUM(C5:C11) -> 0 | D12: =SUM(D5:D11) -> 0 | E12: =SUM(E5:E11) -> 0 | F12: =SUM(F5:F11) -> 0 | G12: =SUM(G5:G11) -> 0 | H12: =SUM(H5:H11) -> 0 | I12: =SUM(I5:I11) -> 0 | ... AF12: =SUM(AF5:AF11) -> 0
A14: ='Section-Category'!A82 -> Petty Cash Used | AF14: Total
A15: ='Section-Category'!A83 -> Pocket Money Wife | AF15: =SUM(B15:AE15) -> 0
A16: ='Section-Category'!A84 -> Car Repair / Workshop | AF16: =SUM(B16:AE16) -> 0
A17: ='Section-Category'!A85 -> Food | AF17: =SUM(B17:AE17) -> 0
A18: ='Section-Category'!A86 -> Donation | AF18: =SUM(B18:AE18) -> 0
A19: Eidi | AF19: =SUM(B19:AE19) -> 0
A20: ='Section-Category'!A88 -> Donation | AF20: =SUM(B20:AE20) -> 0
A21: ='Section-Category'!A89 -> Pocket Money Husband | AF21: =SUM(B21:AE21) -> 0
A22: ='Section-Category'!A90 -> Other | AF22: =SUM(B22:AE22) -> 0
A23: ='Section-Category'!A91 -> Total Petty Cash Used | B23: =SUM(B15:B22) -> 0 | C23: =SUM(C15:C22) -> 0 | D23: =SUM(D15:D22) -> 0 | E23: =SUM(E15:E22) -> 0 | F23: =SUM(F15:F22) -> 0 | G23: =SUM(G15:G22) -> 0 | H23: =SUM(H15:H22) -> 0 | I23: =SUM(I15:I22) -> 0 | ... AF23: =SUM(AF15:AF22) -> 0
A25: ='Section-Category'!A11 -> SAVINGS EXPENSE | AF25: Total
A26: ='Section-Category'!A12 -> Emergency Fund | AF26: =SUM(B26:AE26) -> 0
A27: ='Section-Category'!A13 -> Investments | AF27: =SUM(B27:AE27) -> 0
A28: ='Section-Category'!A14 -> Pocket Money Wife | AF28: =SUM(B28:AE28) -> 0
A29: ='Section-Category'!A15 -> <Name-Of-Entry> | AF29: =SUM(B29:AE29) -> 0
A30: ='Section-Category'!A16 -> <Name-Of-Entry> | AF30: =SUM(B30:AE30) -> 0
A31: ='Section-Category'!A17 -> Total SAVINGS EXPENSE | B31: =SUM(B26:B30) -> 0 | C31: =SUM(C26:C30) -> 0 | D31: =SUM(D26:D30) -> 0 | E31: =SUM(E26:E30) -> 0 | F31: =SUM(F26:F30) -> 0 | G31: =SUM(G26:G30) -> 0 | H31: =SUM(H26:H30) -> 0 | I31: =SUM(I26:I30) -> 0 | ... AF31: =SUM(AF26:AF30) -> 0
A33: ='Section-Category'!A20 -> HOME EXPENSES | AF33: Total
A34: ='Section-Category'!A21 -> Mortgage/Rent | AF34: =SUM(B34:AE34) -> 0
A35: ='Section-Category'!A22 -> Electricity | AF35: =SUM(B35:AE35) -> 0
A36: ='Section-Category'!A23 -> Gas/Oil | AF36: =SUM(B36:AE36) -> 0
A37: ='Section-Category'!A24 -> Water/Sewer/Trash | AF37: =SUM(B37:AE37) -> 0
A38: ='Section-Category'!A25 -> Phone | AF38: =SUM(B38:AE38) -> 0
A39: ='Section-Category'!A26 -> Cable/Satellite | AF39: =SUM(B39:AE39) -> 0
A40: ='Section-Category'!A27 -> Internet | AF40: =SUM(B40:AE40) -> 0
A41: ='Section-Category'!A28 -> Furnishings/Appliances | AF41: =SUM(B41:AE41) -> 0
A42: ='Section-Category'!A29 -> Lawn/Garden | AF42: =SUM(B42:AE42) -> 0
A43: ='Section-Category'!A30 -> Home Supplies | AF43: =SUM(B43:AE43) -> 0
A44: ='Section-Category'!A31 -> Maintenance | AF44: =SUM(B44:AE44) -> 0
...

Sheet May
A1: =MID(CELL("filename",A1),FIND("]",CELL("filename",A1))+1,255) -> May | B1: =Budget!D1 -> 2026
A2: Summary | B2: ='Section-Category'!D10 -> 46143 | C2: ='Section-Category'!E10 -> 46144 | D2: ='Section-Category'!F10 -> 46145 | E2: ='Section-Category'!G10 -> 46146 | F2: ='Section-Category'!H10 -> 46147 | G2: ='Section-Category'!I10 -> 46148 | H2: ='Section-Category'!J10 -> 46149 | I2: ='Section-Category'!K10 -> 46150 | ... AG2: ='Section-Category'!AI10 -> 0 | AH2: Total Sum
A4: INCOME | AH4: Total
A5: Wages & Tips | AH5: =SUM(B5:AG5) -> 0
A6: Interest Income | AH6: =SUM(B6:AG6) -> 0
A7: Dividends | AH7: =SUM(B7:AG7) -> 0
A8: Gifts Received | AH8: =SUM(B8:AG8) -> 0
A9: Refunds/Reimbursements | AH9: =SUM(B9:AG9) -> 0
A10: Other | AH10: =SUM(B10:AG10) -> 0
A11: Transfer From Savings | AH11: =SUM(B11:AG11) -> 0
A12: ='Section-Category'!A9 -> Total INCOME | B12: =SUM(B5:B11) -> 0 | C12: =SUM(C5:C11) -> 0 | D12: =SUM(D5:D11) -> 0 | E12: =SUM(E5:E11) -> 0 | F12: =SUM(F5:F11) -> 0 | G12: =SUM(G5:G11) -> 0 | H12: =SUM(H5:H11) -> 0 | I12: =SUM(I5:I11) -> 0 | ... AE12: =SUM(AE5:AE11) -> 0 | AG12: =SUM(AG5:AG11) -> 0 | AH12: =SUM(AH5:AH11) -> 0
A14: ='Section-Category'!A82 -> Petty Cash Used | AH14: Total
A15: ='Section-Category'!A83 -> Pocket Money Wife | AH15: =SUM(B15:AG15) -> 0
A16: ='Section-Category'!A84 -> Car Repair / Workshop | AH16: =SUM(B16:AG16) -> 0
A17: ='Section-Category'!A85 -> Food | AH17: =SUM(B17:AG17) -> 0
A18: ='Section-Category'!A86 -> Donation | AH18: =SUM(B18:AG18) -> 0
A19: Eidi | AH19: =SUM(B19:AG19) -> 0
A20: ='Section-Category'!A88 -> Donation | AH20: =SUM(B20:AG20) -> 0
A21: ='Section-Category'!A89 -> Pocket Money Husband | AH21: =SUM(B21:AG21) -> 0
A22: ='Section-Category'!A90 -> Other | AH22: =SUM(B22:AG22) -> 0
A23: ='Section-Category'!A91 -> Total Petty Cash Used | B23: =SUM(B15:B22) -> 0 | C23: =SUM(C15:C22) -> 0 | D23: =SUM(D15:D22) -> 0 | E23: =SUM(E15:E22) -> 0 | F23: =SUM(F15:F22) -> 0 | G23: =SUM(G15:G22) -> 0 | H23: =SUM(H15:H22) -> 0 | I23: =SUM(I15:I22) -> 0 | ... AE23: =SUM(AE15:AE22) -> 0 | AG23: =SUM(AG15:AG22) -> 0 | AH23: =SUM(AH15:AH22) -> 0
A25: ='Section-Category'!A11 -> SAVINGS EXPENSE | AH25: Total
A26: ='Section-Category'!A12 -> Emergency Fund | AH26: =SUM(B26:AG26) -> 0
A27: ='Section-Category'!A13 -> Investments | AH27: =SUM(B27:AG27) -> 0
A28: ='Section-Category'!A14 -> Pocket Money Wife | AH28: =SUM(B28:AG28) -> 0
A29: ='Section-Category'!A15 -> <Name-Of-Entry> | AH29: =SUM(B29:AG29) -> 0
A30: ='Section-Category'!A16 -> <Name-Of-Entry> | AH30: =SUM(B30:AG30) -> 0
A31: ='Section-Category'!A17 -> Total SAVINGS EXPENSE | B31: =SUM(B26:B30) -> 0 | C31: =SUM(C26:C30) -> 0 | D31: =SUM(D26:D30) -> 0 | E31: =SUM(E26:E30) -> 0 | F31: =SUM(F26:F30) -> 0 | G31: =SUM(G26:G30) -> 0 | H31: =SUM(H26:H30) -> 0 | I31: =SUM(I26:I30) -> 0 | ... AE31: =SUM(AE26:AE30) -> 0 | AG31: =SUM(AG26:AG30) -> 0 | AH31: =SUM(AH26:AH30) -> 0
A33: ='Section-Category'!A20 -> HOME EXPENSES | AH33: Total
A34: ='Section-Category'!A21 -> Mortgage/Rent | AH34: =SUM(B34:AG34) -> 0
A35: ='Section-Category'!A22 -> Electricity | AH35: =SUM(B35:AG35) -> 0
A36: ='Section-Category'!A23 -> Gas/Oil | AH36: =SUM(B36:AG36) -> 0
A37: ='Section-Category'!A24 -> Water/Sewer/Trash | AH37: =SUM(B37:AG37) -> 0
A38: ='Section-Category'!A25 -> Phone | AH38: =SUM(B38:AG38) -> 0
A39: ='Section-Category'!A26 -> Cable/Satellite | AH39: =SUM(B39:AG39) -> 0
A40: ='Section-Category'!A27 -> Internet | AH40: =SUM(B40:AG40) -> 0
A41: ='Section-Category'!A28 -> Furnishings/Appliances | AH41: =SUM(B41:AG41) -> 0
A42: ='Section-Category'!A29 -> Lawn/Garden | AH42: =SUM(B42:AG42) -> 0
A43: ='Section-Category'!A30 -> Home Supplies | AH43: =SUM(B43:AG43) -> 0
A44: ='Section-Category'!A31 -> Maintenance | AH44: =SUM(B44:AG44) -> 0
...

Sheet Jun
A1: =MID(CELL("filename",A1),FIND("]",CELL("filename",A1))+1,255) -> Jun | B1: =Budget!D1 -> 2026
A2: Summary/Date | B2: ='Section-Category'!D11 -> 46174 | C2: ='Section-Category'!E11 -> 46175 | D2: ='Section-Category'!F11 -> 46176 | E2: ='Section-Category'!G11 -> 46177 | F2: ='Section-Category'!H11 -> 46178 | G2: ='Section-Category'!I11 -> 46179 | H2: ='Section-Category'!J11 -> 46180 | I2: ='Section-Category'!K11 -> 46181 | ... AE2: ='Section-Category'!AG11 -> 46203 | AF2: Total Sum
A4: INCOME | AF4: Total
A5: Wages & Tips | AF5: =SUM(B5:AE5) -> 0
A6: Interest Income | AF6: =SUM(B6:AE6) -> 0
A7: Dividends | AF7: =SUM(B7:AE7) -> 0
A8: Gifts Received | AF8: =SUM(B8:AE8) -> 0
A9: Refunds/Reimbursements | AF9: =SUM(B9:AE9) -> 0
A10: Other | AF10: =SUM(B10:AE10) -> 0
A11: Transfer From Savings | AF11: =SUM(B11:AE11) -> 0
A12: ='Section-Category'!A9 -> Total INCOME | B12: =SUM(B5:B11) -> 0 | C12: =SUM(C5:C11) -> 0 | D12: =SUM(D5:D11) -> 0 | E12: =SUM(E5:E11) -> 0 | F12: =SUM(F5:F11) -> 0 | G12: =SUM(G5:G11) -> 0 | H12: =SUM(H5:H11) -> 0 | I12: =SUM(I5:I11) -> 0 | ... AF12: =SUM(AF5:AF11) -> 0
A14: ='Section-Category'!A82 -> Petty Cash Used | AF14: Total
A15: ='Section-Category'!A83 -> Pocket Money Wife | AF15: =SUM(B15:AE15) -> 0
A16: ='Section-Category'!A84 -> Car Repair / Workshop | AF16: =SUM(B16:AE16) -> 0
A17: ='Section-Category'!A85 -> Food | AF17: =SUM(B17:AE17) -> 0
A18: ='Section-Category'!A86 -> Donation | AF18: =SUM(B18:AE18) -> 0
A19: Eidi | AF19: =SUM(B19:AE19) -> 0
A20: ='Section-Category'!A88 -> Donation | AF20: =SUM(B20:AE20) -> 0
A21: ='Section-Category'!A89 -> Pocket Money Husband | AF21: =SUM(B21:AE21) -> 0
A22: ='Section-Category'!A90 -> Other | AF22: =SUM(B22:AE22) -> 0
A23: ='Section-Category'!A91 -> Total Petty Cash Used | B23: =SUM(B15:B22) -> 0 | C23: =SUM(C15:C22) -> 0 | D23: =SUM(D15:D22) -> 0 | E23: =SUM(E15:E22) -> 0 | F23: =SUM(F15:F22) -> 0 | G23: =SUM(G15:G22) -> 0 | H23: =SUM(H15:H22) -> 0 | I23: =SUM(I15:I22) -> 0 | ... AF23: =SUM(AF15:AF22) -> 0
A25: ='Section-Category'!A11 -> SAVINGS EXPENSE | AF25: Total
A26: ='Section-Category'!A12 -> Emergency Fund | AF26: =SUM(B26:AE26) -> 0
A27: ='Section-Category'!A13 -> Investments | AF27: =SUM(B27:AE27) -> 0
A28: ='Section-Category'!A14 -> Pocket Money Wife | AF28: =SUM(B28:AE28) -> 0
A29: ='Section-Category'!A15 -> <Name-Of-Entry> | AF29: =SUM(B29:AE29) -> 0
A30: ='Section-Category'!A16 -> <Name-Of-Entry> | AF30: =SUM(B30:AE30) -> 0
A31: ='Section-Category'!A17 -> Total SAVINGS EXPENSE | B31: =SUM(B26:B30) -> 0 | C31: =SUM(C26:C30) -> 0 | D31: =SUM(D26:D30) -> 0 | E31: =SUM(E26:E30) -> 0 | F31: =SUM(F26:F30) -> 0 | G31: =SUM(G26:G30) -> 0 | H31: =SUM(H26:H30) -> 0 | I31: =SUM(I26:I30) -> 0 | ... AF31: =SUM(AF26:AF30) -> 0
A33: ='Section-Category'!A20 -> HOME EXPENSES | AF33: Total
A34: ='Section-Category'!A21 -> Mortgage/Rent | AF34: =SUM(B34:AE34) -> 0
A35: ='Section-Category'!A22 -> Electricity | AF35: =SUM(B35:AE35) -> 0
A36: ='Section-Category'!A23 -> Gas/Oil | AF36: =SUM(B36:AE36) -> 0
A37: ='Section-Category'!A24 -> Water/Sewer/Trash | AF37: =SUM(B37:AE37) -> 0
A38: ='Section-Category'!A25 -> Phone | AF38: =SUM(B38:AE38) -> 0
A39: ='Section-Category'!A26 -> Cable/Satellite | AF39: =SUM(B39:AE39) -> 0
A40: ='Section-Category'!A27 -> Internet | AF40: =SUM(B40:AE40) -> 0
A41: ='Section-Category'!A28 -> Furnishings/Appliances | AF41: =SUM(B41:AE41) -> 0
A42: ='Section-Category'!A29 -> Lawn/Garden | AF42: =SUM(B42:AE42) -> 0
A43: ='Section-Category'!A30 -> Home Supplies | AF43: =SUM(B43:AE43) -> 0
A44: ='Section-Category'!A31 -> Maintenance | AF44: =SUM(B44:AE44) -> 0
...

Sheet Jul
A1: =MID(CELL("filename",A1),FIND("]",CELL("filename",A1))+1,255) -> Jul | B1: =Budget!D1 -> 2026
A2: Summary/Date | B2: ='Section-Category'!D12 -> 46204 | C2: ='Section-Category'!E12 -> 46205 | D2: ='Section-Category'!F12 -> 46206 | E2: ='Section-Category'!G12 -> 46207 | F2: ='Section-Category'!H12 -> 46208 | G2: ='Section-Category'!I12 -> 46209 | H2: ='Section-Category'!J12 -> 46210 | I2: ='Section-Category'!K12 -> 46211 | ... AE2: ='Section-Category'!AG12 -> 46233 | AF2: Total Sum
A4: INCOME | AF4: Total
A5: Wages & Tips | AF5: =SUM(B5:AE5) -> 0
A6: Interest Income | AF6: =SUM(B6:AE6) -> 0
A7: Dividends | AF7: =SUM(B7:AE7) -> 0
A8: Gifts Received | AF8: =SUM(B8:AE8) -> 0
A9: Refunds/Reimbursements | AF9: =SUM(B9:AE9) -> 0
A10: Other | AF10: =SUM(B10:AE10) -> 0
A11: Transfer From Savings | AF11: =SUM(B11:AE11) -> 0
A12: ='Section-Category'!A9 -> Total INCOME | B12: =SUM(B5:B11) -> 0 | C12: =SUM(C5:C11) -> 0 | D12: =SUM(D5:D11) -> 0 | E12: =SUM(E5:E11) -> 0 | F12: =SUM(F5:F11) -> 0 | G12: =SUM(G5:G11) -> 0 | H12: =SUM(H5:H11) -> 0 | I12: =SUM(I5:I11) -> 0 | ... AF12: =SUM(AF5:AF11) -> 0
A14: ='Section-Category'!A82 -> Petty Cash Used | AF14: Total
A15: ='Section-Category'!A83 -> Pocket Money Wife | AF15: =SUM(B15:AE15) -> 0
A16: ='Section-Category'!A84 -> Car Repair / Workshop | AF16: =SUM(B16:AE16) -> 0
A17: ='Section-Category'!A85 -> Food | AF17: =SUM(B17:AE17) -> 0
A18: ='Section-Category'!A86 -> Donation | AF18: =SUM(B18:AE18) -> 0
A19: Eidi | AF19: =SUM(B19:AE19) -> 0
A20: ='Section-Category'!A88 -> Donation | AF20: =SUM(B20:AE20) -> 0
A21: ='Section-Category'!A89 -> Pocket Money Husband | AF21: =SUM(B21:AE21) -> 0
A22: ='Section-Category'!A90 -> Other | AF22: =SUM(B22:AE22) -> 0
A23: ='Section-Category'!A91 -> Total Petty Cash Used | B23: =SUM(B15:B22) -> 0 | C23: =SUM(C15:C22) -> 0 | D23: =SUM(D15:D22) -> 0 | E23: =SUM(E15:E22) -> 0 | F23: =SUM(F15:F22) -> 0 | G23: =SUM(G15:G22) -> 0 | H23: =SUM(H15:H22) -> 0 | I23: =SUM(I15:I22) -> 0 | ... AF23: =SUM(AF15:AF22) -> 0
A25: ='Section-Category'!A11 -> SAVINGS EXPENSE | AF25: Total
A26: ='Section-Category'!A12 -> Emergency Fund | AF26: =SUM(B26:AE26) -> 0
A27: ='Section-Category'!A13 -> Investments | AF27: =SUM(B27:AE27) -> 0
A28: ='Section-Category'!A14 -> Pocket Money Wife | AF28: =SUM(B28:AE28) -> 0
A29: ='Section-Category'!A15 -> <Name-Of-Entry> | AF29: =SUM(B29:AE29) -> 0
A30: ='Section-Category'!A16 -> <Name-Of-Entry> | AF30: =SUM(B30:AE30) -> 0
A31: ='Section-Category'!A17 -> Total SAVINGS EXPENSE | B31: =SUM(B26:B30) -> 0 | C31: =SUM(C26:C30) -> 0 | D31: =SUM(D26:D30) -> 0 | E31: =SUM(E26:E30) -> 0 | F31: =SUM(F26:F30) -> 0 | G31: =SUM(G26:G30) -> 0 | H31: =SUM(H26:H30) -> 0 | I31: =SUM(I26:I30) -> 0 | ... AF31: =SUM(AF26:AF30) -> 0
A33: ='Section-Category'!A20 -> HOME EXPENSES | AF33: Total
A34: ='Section-Category'!A21 -> Mortgage/Rent | AF34: =SUM(B34:AE34) -> 0
A35: ='Section-Category'!A22 -> Electricity | AF35: =SUM(B35:AE35) -> 0
A36: ='Section-Category'!A23 -> Gas/Oil | AF36: =SUM(B36:AE36) -> 0
A37: ='Section-Category'!A24 -> Water/Sewer/Trash | AF37: =SUM(B37:AE37) -> 0
A38: ='Section-Category'!A25 -> Phone | AF38: =SUM(B38:AE38) -> 0
A39: ='Section-Category'!A26 -> Cable/Satellite | AF39: =SUM(B39:AE39) -> 0
A40: ='Section-Category'!A27 -> Internet | AF40: =SUM(B40:AE40) -> 0
A41: ='Section-Category'!A28 -> Furnishings/Appliances | AF41: =SUM(B41:AE41) -> 0
